Workbook
Name Arrendamento_total: #REF!
Name Porcentagem_Gestão: #REF!
Name TUSDg_total: #REF!

Sheet Infos Clientes
Q1: =MAX('Detalhe Por UC'!R:R) -> 45962 | T1: =SUBTOTAL(9,T3:T873) -> 36941.467 | U1: =SUBTOTAL(9,U3:U873) -> 37613.277
B2: INSTALACAO | C2: Linha | D2: Nome/Razão Social | E2: Região | F2: CPF/CNPJ | G2: E-mail | H2: INSTALACAO | I2: TENSAO | J2: MEDIDOR | K2: USINA | L2: CAPTADOR COMERCIAL | M2: Desconto sobre Tarifa Compensada ATUAL (Se teve alteração vai estar no próprio relatório ref. meses anteriores) | N2: Meses com desconto em dobro | O2: Tempo de Fidelidade (meses) | P2: Status | Q2: 1º mês compensação | R2: Meses remanescente de fidelidade | T2: Participação no consorcio kWh inicial (90% do consumo) | U2: Média Consumo | W2: 45261 | X2: 45292 | Y2: 45323 | Z2: 45352 | AA2: 45383 | AB2: 45413 | AC2: 45444 | AD2: 45474 | AE2: 45505 | AF2: 45536 | AG2: 45566 | AH2: 45597 | AI2: 45627 | AJ2: 45658 | AK2: 45689 | AL2: 45717 | AM2: 45748 | AN2: 45778 | AO2: 45809 | AP2: 45839 | AQ2: 45870 | AR2: 45901 | AS2: 45931 | AT2: 45962 | AU2: 45992 | AV2: 46023 | AW2: 46054 | AX2: 46082 | AY2: 46113 | AZ2: 46143 | BA2: 46174 | BB2: 46204 | BC2: 46235 | BD2: 46266 | BE2: 46296 | BF2: 46327 | BG2: 46357 | BH2: 46388 | BI2: 46419 | BJ2: 46447 | BK2: 46478 | BL2: 46508 | BM2: 46539 | BN2: 46569 | BO2: 46600 | BP2: 46631 | BQ2: 46661 | BR2: 46692 | BS2: 46722
B3: 10/10232-7 | C3: =ROW(F3) -> 3 | D3: IGREJA DO EVANGELHO QUADRANGULAR | E3: 302 | F3: 62.955.505/3932-07 | G3: katiaconceicaogomes2020@gmail.com; israelregiao302@gmail.com | H3: 10/10232-7 | I3: BT | J3: bifasico | K3: GIROSSOL II | M3: 0.25 | Q3: =IF(_xlfn.MINIFS('Detalhe Por UC'!R:R,'Detalhe Por UC'!C:C,B3,'Detalhe Por UC'!AD:AD,">"&0)=0,"",_xlfn.MINIFS('Detalhe Por UC'!R:R,'Detalhe Por UC'!C:C,B3,'Detalhe Por UC'!AD:AD,">"&0)) -> 45627 | R3: =IF(P3<>"ATIVO",0, IF(OR(Q3="",Q3=0,O3=0),O3, O3-ROUND((MAX('Detalhe Por UC'!R:R) -Q3)/(365/12),0))) -> 0 | T3: 99.833333 | U3: =IFERROR((SUMIFS(W3:CN3,$W$2:$CN$2,">"&$Q$1-365,$W$2:$CN$2,"<="&$Q$1)/COUNTIFS(W3:CN3,">="&0,$W$2:$CN$2,">"&$Q$1-365,$W$2:$CN$2,"<="&$Q$1)),"") -> 153.83333 | W3: 114 | X3: 108 | Y3: 78 | Z3: 109 | AA3: 96 | AB3: 155 | AC3: 119 | AD3: 72 | AE3: 77 | AF3: 88 | AG3: 116 | AH3: 113 | AI3: 82 | AJ3: =IF(SUMIFS('Detalhe Por UC'!$AB:$AB,'Detalhe Por UC'!$C:$C,'Infos Clientes'!$B3,'Detalhe Por UC'!$R:$R,'Infos Clientes'!AJ$2)=0,"", SUMIFS('Detalhe Por UC'!$AB:$AB,'Detalhe Por UC'!$C:$C,'Infos Clientes'!$B3,'Detalhe Por UC'!$R:$R,'Infos Clientes'!AJ$2) +SUMIFS('Detalhe Por UC'!$AC:$AC,'Detalhe Por UC'!$C:$C,'Infos Clientes'!$B3,'Detalhe Por UC'!$R:$R,'Infos Clientes'!AJ$2)) -> 93 | AK3: =IF(SUMIFS('Detalhe Por UC'!$AB:$AB,'Detalhe Por UC'!$C:$C,'Infos Clientes'!$B3,'Detalhe Por UC'!$R:$R,'Infos Clientes'!AK$2)=0,"", SUMIFS('Detalhe Por UC'!$AB:$AB,'Detalhe Por UC'!$C:$C,'Infos Clientes'!$B3,'Detalhe Por UC'!$R:$R,'Infos Clientes'!AK$2) +SUMIFS('Detalhe Por UC'!$AC:$AC,'Detalhe Por UC'!$C:$C,'Infos Clientes'!$B3,'Detalhe Por UC'!$R:$R,'Infos Clientes'!AK$2)) -> 203 | AL3: =IF(SUMIFS('Detalhe Por UC'!$AB:$AB,'Detalhe Por UC'!$C:$C,'Infos Clientes'!$B3,'Detalhe Por UC'!$R:$R,'Infos Clientes'!AL$2)=0,"", SUMIFS('Detalhe Por UC'!$AB:$AB,'Detalhe Por UC'!$C:$C,'Infos Clientes'!$B3,'Detalhe Por UC'!$R:$R,'Infos Clientes'!AL$2) +SUMIFS('Detalhe Por UC'!$AC:$AC,'Detalhe Por UC'!$C:$C,'Infos Clientes'!$B3,'Detalhe Por UC'!$R:$R,'Infos Clientes'!AL$2)) -> 234 | AM3: =IF(SUMIFS('Detalhe Por UC'!$AB:$AB,'Detalhe Por UC'!$C:$C,'Infos Clientes'!$B3,'Detalhe Por UC'!$R:$R,'Infos Clientes'!AM$2)=0,"", SUMIFS('Detalhe Por UC'!$AB:$AB,'Detalhe Por UC'!$C:$C,'Infos Clientes'!$B3,'Detalhe Por UC'!$R:$R,'Infos Clientes'!AM$2) +SUMIFS('Detalhe Por UC'!$AC:$AC,'Detalhe Por UC'!$C:$C,'Infos Clientes'!$B3,'Detalhe Por UC'!$R:$R,'Infos Clientes'!AM$2)) -> 199 | AN3: =IF(SUMIFS('Detalhe Por UC'!$AB:$AB,'Detalhe Por UC'!$C:$C,'Infos Clientes'!$B3,'Detalhe Por UC'!$R:$R,'Infos Clientes'!AN$2)=0,"", SUMIFS('Detalhe Por UC'!$AB:$AB,'Detalhe Por UC'!$C:$C,'Infos Clientes'!$B3,'Detalhe Por UC'!$R:$R,'Infos Clientes'!AN$2) +SUMIFS('Detalhe Por UC'!$AC:$AC,'Detalhe Por UC'!$C:$C,'Infos Clientes'!$B3,'Detalhe Por UC'!$R:$R,'Infos Clientes'!AN$2)) -> 146 | AO3: =IF(SUMIFS('Detalhe Por UC'!$AB:$AB,'Detalhe Por UC'!$C:$C,'Infos Clientes'!$B3,'Detalhe Por UC'!$R:$R,'Infos Clientes'!AO$2)=0,"", SUMIFS('Detalhe Por UC'!$AB:$AB,'Detalhe Por UC'!$C:$C,'Infos Clientes'!$B3,'Detalhe Por UC'!$R:$R,'Infos Clientes'!AO$2) +SUMIFS('Detalhe Por UC'!$AC:$AC,'Detalhe Por UC'!$C:$C,'Infos Clientes'!$B3,'Detalhe Por UC'!$R:$R,'Infos Clientes'!AO$2)) -> 78 | AP3: =IF(SUMIFS('Detalhe Por UC'!$AB:$AB,'Detalhe Por UC'!$C:$C,'Infos Clientes'!$B3,'Detalhe Por UC'!$R:$R,'Infos Clientes'!AP$2)=0,"", SUMIFS('Detalhe Por UC'!$AB:$AB,'Detalhe Por UC'!$C:$C,'Infos Clientes'!$B3,'Detalhe Por UC'!$R:$R,'Infos Clientes'!AP$2) +SUMIFS('Detalhe Por UC'!$AC:$AC,'Detalhe Por UC'!$C:$C,'Infos Clientes'!$B3,'Detalhe Por UC'!$R:$R,'Infos Clientes'!AP$2)) -> 67 | AQ3: =IF(SUMIFS('Detalhe Por UC'!$AB:$AB,'Detalhe Por UC'!$C:$C,'Infos Clientes'!$B3,'Detalhe Por UC'!$R:$R,'Infos Clientes'!AQ$2)=0,"", SUMIFS('Detalhe Por UC'!$AB:$AB,'Detalhe Por UC'!$C:$C,'Infos Clientes'!$B3,'Detalhe Por UC'!$R:$R,'Infos Clientes'!AQ$2) +SUMIFS('Detalhe Por UC'!$AC:$AC,'Detalhe Por UC'!$C:$C,'Infos Clientes'!$B3,'Detalhe Por UC'!$R:$R,'Infos Clientes'!AQ$2)) -> 81 | ... AU3: =IF(SUMIFS('Detalhe Por UC'!$AB:$AB,'Detalhe Por UC'!$C:$C,'Infos Clientes'!$B3,'Detalhe Por UC'!$R:$R,'Infos Clientes'!AU$2)=0,"", SUMIFS('Detalhe Por UC'!$AB:$AB,'Detalhe Por UC'!$C:$C,'Infos Clientes'!$B3,'Detalhe Por UC'!$R:$R,'Infos Clientes'!AU$2) +SUMIFS('Detalhe Por UC'!$AC:$AC,'Detalhe Por UC'!$C:$C,'Infos Clientes'!$B3,'Detalhe Por UC'!$R:$R,'Infos Clientes'!AU$2))
B4: 10/1035655-8 | C4: =ROW(F4) -> 4 | D4: IGREJA DO EVANGELHO QUADRANGULAR | E4: 319 | F4: 62.955.505/1822-57 | G4: evaniabenites@hotmail.com | H4: 10/1035655-8 | I4: BT | J4: trifasico | K4: GIROSSOL II | M4: 0.25 | Q4: =IF(_xlfn.MINIFS('Detalhe Por UC'!R:R,'Detalhe Por UC'!C:C,B4,'Detalhe Por UC'!AD:AD,">"&0)=0,"",_xlfn.MINIFS('Detalhe Por UC'!R:R,'Detalhe Por UC'!C:C,B4,'Detalhe Por UC'!AD:AD,">"&0)) -> 45627 | R4: =IF(P4<>"ATIVO",0, IF(OR(Q4="",Q4=0,O4=0),O4, O4-ROUND((MAX('Detalhe Por UC'!R:R) -Q4)/(365/12),0))) -> 0 | T4: 453.58333 | U4: =IFERROR((SUMIFS(W4:CN4,$W$2:$CN$2,">"&$Q$1-365,$W$2:$CN$2,"<="&$Q$1)/COUNTIFS(W4:CN4,">="&0,$W$2:$CN$2,">"&$Q$1-365,$W$2:$CN$2,"<="&$Q$1)),"") -> 375.91667 | W4: 298 | X4: 455 | Y4: 591 | Z4: 630 | AA4: 540 | AB4: 369 | AC4: 381 | AD4: 214 | AE4: 273 | AF4: 321 | AG4: 385 | AH4: 671 | AI4: 528 | AJ4: =IF(SUMIFS('Detalhe Por UC'!$AB:$AB,'Detalhe Por UC'!$C:$C,'Infos Clientes'!$B4,'Detalhe Por UC'!$R:$R,'Infos Clientes'!AJ$2)=0,"", SUMIFS('Detalhe Por UC'!$AB:$AB,'Detalhe Por UC'!$C:$C,'Infos Clientes'!$B4,'Detalhe Por UC'!$R:$R,'Infos Clientes'!AJ$2) +SUMIFS('Detalhe Por UC'!$AC:$AC,'Detalhe Por UC'!$C:$C,'Infos Clientes'!$B4,'Detalhe Por UC'!$R:$R,'Infos Clientes'!AJ$2)) -> 540 | AK4: =IF(SUMIFS('Detalhe Por UC'!$AB:$AB,'Detalhe Por UC'!$C:$C,'Infos Clientes'!$B4,'Detalhe Por UC'!$R:$R,'Infos Clientes'!AK$2)=0,"", SUMIFS('Detalhe Por UC'!$AB:$AB,'Detalhe Por UC'!$C:$C,'Infos Clientes'!$B4,'Detalhe Por UC'!$R:$R,'Infos Clientes'!AK$2) +SUMIFS('Detalhe Por UC'!$AC:$AC,'Detalhe Por UC'!$C:$C,'Infos Clientes'!$B4,'Detalhe Por UC'!$R:$R,'Infos Clientes'!AK$2)) -> 433 | AL4: =IF(SUMIFS('Detalhe Por UC'!$AB:$AB,'Detalhe Por UC'!$C:$C,'Infos Clientes'!$B4,'Detalhe Por UC'!$R:$R,'Infos Clientes'!AL$2)=0,"", SUMIFS('Detalhe Por UC'!$AB:$AB,'Detalhe Por UC'!$C:$C,'Infos Clientes'!$B4,'Detalhe Por UC'!$R:$R,'Infos Clientes'!AL$2) +SUMIFS('Detalhe Por UC'!$AC:$AC,'Detalhe Por UC'!$C:$C,'Infos Clientes'!$B4,'Detalhe Por UC'!$R:$R,'Infos Clientes'!AL$2)) -> 581 | AM4: =IF(SUMIFS('Detalhe Por UC'!$AB:$AB,'Detalhe Por UC'!$C:$C,'Infos Clientes'!$B4,'Detalhe Por UC'!$R:$R,'Infos Clientes'!AM$2)=0,"", SUMIFS('Detalhe Por UC'!$AB:$AB,'Detalhe Por UC'!$C:$C,'Infos Clientes'!$B4,'Detalhe Por UC'!$R:$R,'Infos Clientes'!AM$2) +SUMIFS('Detalhe Por UC'!$AC:$AC,'Detalhe Por UC'!$C:$C,'Infos Clientes'!$B4,'Detalhe Por UC'!$R:$R,'Infos Clientes'!AM$2)) -> 338 | AN4: =IF(SUMIFS('Detalhe Por UC'!$AB:$AB,'Detalhe Por UC'!$C:$C,'Infos Clientes'!$B4,'Detalhe Por UC'!$R:$R,'Infos Clientes'!AN$2)=0,"", SUMIFS('Detalhe Por UC'!$AB:$AB,'Detalhe Por UC'!$C:$C,'Infos Clientes'!$B4,'Detalhe Por UC'!$R:$R,'Infos Clientes'!AN$2) +SUMIFS('Detalhe Por UC'!$AC:$AC,'Detalhe Por UC'!$C:$C,'Infos Clientes'!$B4,'Detalhe Por UC'!$R:$R,'Infos Clientes'!AN$2)) -> 259 | AO4: =IF(SUMIFS('Detalhe Por UC'!$AB:$AB,'Detalhe Por UC'!$C:$C,'Infos Clientes'!$B4,'Detalhe Por UC'!$R:$R,'Infos Clientes'!AO$2)=0,"", SUMIFS('Detalhe Por UC'!$AB:$AB,'Detalhe Por UC'!$C:$C,'Infos Clientes'!$B4,'Detalhe Por UC'!$R:$R,'Infos Clientes'!AO$2) +SUMIFS('Detalhe Por UC'!$AC:$AC,'Detalhe Por UC'!$C:$C,'Infos Clientes'!$B4,'Detalhe Por UC'!$R:$R,'Infos Clientes'!AO$2)) -> 272 | AP4: =IF(SUMIFS('Detalhe Por UC'!$AB:$AB,'Detalhe Por UC'!$C:$C,'Infos Clientes'!$B4,'Detalhe Por UC'!$R:$R,'Infos Clientes'!AP$2)=0,"", SUMIFS('Detalhe Por UC'!$AB:$AB,'Detalhe Por UC'!$C:$C,'Infos Clientes'!$B4,'Detalhe Por UC'!$R:$R,'Infos Clientes'!AP$2) +SUMIFS('Detalhe Por UC'!$AC:$AC,'Detalhe Por UC'!$C:$C,'Infos Clientes'!$B4,'Detalhe Por UC'!$R:$R,'Infos Clientes'!AP$2)) -> 172 | AQ4: =IF(SUMIFS('Detalhe Por UC'!$AB:$AB,'Detalhe Por UC'!$C:$C,'Infos Clientes'!$B4,'Detalhe Por UC'!$R:$R,'Infos Clientes'!AQ$2)=0,"", SUMIFS('Detalhe Por UC'!$AB:$AB,'Detalhe Por UC'!$C:$C,'Infos Clientes'!$B4,'Detalhe Por UC'!$R:$R,'Infos Clientes'!AQ$2) +SUMIFS('Detalhe Por UC'!$AC:$AC,'Detalhe Por UC'!$C:$C,'Infos Clientes'!$B4,'Detalhe Por UC'!$R:$R,'Infos Clientes'!AQ$2)) -> 205 | ... AU4: =IF(SUMIFS('Detalhe Por UC'!$AB:$AB,'Detalhe Por UC'!$C:$C,'Infos Clientes'!$B4,'Detalhe Por UC'!$R:$R,'Infos Clientes'!AU$2)=0,"", SUMIFS('Detalhe Por UC'!$AB:$AB,'Detalhe Por UC'!$C:$C,'Infos Clientes'!$B4,'Detalhe Por UC'!$R:$R,'Infos Clientes'!AU$2) +SUMIFS('Detalhe Por UC'!$AC:$AC,'Detalhe Por UC'!$C:$C,'Infos Clientes'!$B4,'Detalhe Por UC'!$R:$R,'Infos Clientes'!AU$2))
B5: 10/1117293-9 | C5: =ROW(F5) -> 5 | D5: IGREJA DO EVANGELHO QUADRANGULAR | E5: 362 | F5: 62.955.505/8921-14 | G5: pastordamilton@gmail.com | H5: 10/1117293-9 | I5: BT | J5: trifasico | K5: GIROSSOL II | M5: 0.25 | Q5: =IF(_xlfn.MINIFS('Detalhe Por UC'!R:R,'Detalhe Por UC'!C:C,B5,'Detalhe Por UC'!AD:AD,">"&0)=0,"",_xlfn.MINIFS('Detalhe Por UC'!R:R,'Detalhe Por UC'!C:C,B5,'Detalhe Por UC'!AD:AD,">"&0)) -> 45627 | R5: =IF(P5<>"ATIVO",0, IF(OR(Q5="",Q5=0,O5=0),O5, O5-ROUND((MAX('Detalhe Por UC'!R:R) -Q5)/(365/12),0))) -> 0 | T5: 178.41667 | U5: =IFERROR((SUMIFS(W5:CN5,$W$2:$CN$2,">"&$Q$1-365,$W$2:$CN$2,"<="&$Q$1)/COUNTIFS(W5:CN5,">="&0,$W$2:$CN$2,">"&$Q$1-365,$W$2:$CN$2,"<="&$Q$1)),"") -> 161.33333 | W5: 163 | X5: 185 | Y5: 161 | Z5: 221 | AA5: 180 | AB5: 165 | AC5: 160 | AD5: 145 | AE5: 160 | AF5: 152 | AG5: 175 | AH5: 179 | AI5: 161 | AJ5: =IF(SUMIFS('Detalhe Por UC'!$AB:$AB,'Detalhe Por UC'!$C:$C,'Infos Clientes'!$B5,'Detalhe Por UC'!$R:$R,'Infos Clientes'!AJ$2)=0,"", SUMIFS('Detalhe Por UC'!$AB:$AB,'Detalhe Por UC'!$C:$C,'Infos Clientes'!$B5,'Detalhe Por UC'!$R:$R,'Infos Clientes'!AJ$2) +SUMIFS('Detalhe Por UC'!$AC:$AC,'Detalhe Por UC'!$C:$C,'Infos Clientes'!$B5,'Detalhe Por UC'!$R:$R,'Infos Clientes'!AJ$2)) -> 282 | AK5: =IF(SUMIFS('Detalhe Por UC'!$AB:$AB,'Detalhe Por UC'!$C:$C,'Infos Clientes'!$B5,'Detalhe Por UC'!$R:$R,'Infos Clientes'!AK$2)=0,"", SUMIFS('Detalhe Por UC'!$AB:$AB,'Detalhe Por UC'!$C:$C,'Infos Clientes'!$B5,'Detalhe Por UC'!$R:$R,'Infos Clientes'!AK$2) +SUMIFS('Detalhe Por UC'!$AC:$AC,'Detalhe Por UC'!$C:$C,'Infos Clientes'!$B5,'Detalhe Por UC'!$R:$R,'Infos Clientes'!AK$2)) -> 171 | AL5: =IF(SUMIFS('Detalhe Por UC'!$AB:$AB,'Detalhe Por UC'!$C:$C,'Infos Clientes'!$B5,'Detalhe Por UC'!$R:$R,'Infos Clientes'!AL$2)=0,"", SUMIFS('Detalhe Por UC'!$AB:$AB,'Detalhe Por UC'!$C:$C,'Infos Clientes'!$B5,'Detalhe Por UC'!$R:$R,'Infos Clientes'!AL$2) +SUMIFS('Detalhe Por UC'!$AC:$AC,'Detalhe Por UC'!$C:$C,'Infos Clientes'!$B5,'Detalhe Por UC'!$R:$R,'Infos Clientes'!AL$2)) -> 185 | AM5: =IF(SUMIFS('Detalhe Por UC'!$AB:$AB,'Detalhe Por UC'!$C:$C,'Infos Clientes'!$B5,'Detalhe Por UC'!$R:$R,'Infos Clientes'!AM$2)=0,"", SUMIFS('Detalhe Por UC'!$AB:$AB,'Detalhe Por UC'!$C:$C,'Infos Clientes'!$B5,'Detalhe Por UC'!$R:$R,'Infos Clientes'!AM$2) +SUMIFS('Detalhe Por UC'!$AC:$AC,'Detalhe Por UC'!$C:$C,'Infos Clientes'!$B5,'Detalhe Por UC'!$R:$R,'Infos Clientes'!AM$2)) -> 176 | AN5: =IF(SUMIFS('Detalhe Por UC'!$AB:$AB,'Detalhe Por UC'!$C:$C,'Infos Clientes'!$B5,'Detalhe Por UC'!$R:$R,'Infos Clientes'!AN$2)=0,"", SUMIFS('Detalhe Por UC'!$AB:$AB,'Detalhe Por UC'!$C:$C,'Infos Clientes'!$B5,'Detalhe Por UC'!$R:$R,'Infos Clientes'!AN$2) +SUMIFS('Detalhe Por UC'!$AC:$AC,'Detalhe Por UC'!$C:$C,'Infos Clientes'!$B5,'Detalhe Por UC'!$R:$R,'Infos Clientes'!AN$2)) -> 153 | AO5: =IF(SUMIFS('Detalhe Por UC'!$AB:$AB,'Detalhe Por UC'!$C:$C,'Infos Clientes'!$B5,'Detalhe Por UC'!$R:$R,'Infos Clientes'!AO$2)=0,"", SUMIFS('Detalhe Por UC'!$AB:$AB,'Detalhe Por UC'!$C:$C,'Infos Clientes'!$B5,'Detalhe Por UC'!$R:$R,'Infos Clientes'!AO$2) +SUMIFS('Detalhe Por UC'!$AC:$AC,'Detalhe Por UC'!$C:$C,'Infos Clientes'!$B5,'Detalhe Por UC'!$R:$R,'Infos Clientes'!AO$2)) -> 118 | AP5: =IF(SUMIFS('Detalhe Por UC'!$AB:$AB,'Detalhe Por UC'!$C:$C,'Infos Clientes'!$B5,'Detalhe Por UC'!$R:$R,'Infos Clientes'!AP$2)=0,"", SUMIFS('Detalhe Por UC'!$AB:$AB,'Detalhe Por UC'!$C:$C,'Infos Clientes'!$B5,'Detalhe Por UC'!$R:$R,'Infos Clientes'!AP$2) +SUMIFS('Detalhe Por UC'!$AC:$AC,'Detalhe Por UC'!$C:$C,'Infos Clientes'!$B5,'Detalhe Por UC'!$R:$R,'Infos Clientes'!AP$2)) -> 115 | AQ5: =IF(SUMIFS('Detalhe Por UC'!$AB:$AB,'Detalhe Por UC'!$C:$C,'Infos Clientes'!$B5,'Detalhe Por UC'!$R:$R,'Infos Clientes'!AQ$2)=0,"", SUMIFS('Detalhe Por UC'!$AB:$AB,'Detalhe Por UC'!$C:$C,'Infos Clientes'!$B5,'Detalhe Por UC'!$R:$R,'Infos Clientes'!AQ$2) +SUMIFS('Detalhe Por UC'!$AC:$AC,'Detalhe Por UC'!$C:$C,'Infos Clientes'!$B5,'Detalhe Por UC'!$R:$R,'Infos Clientes'!AQ$2)) -> 121 | ... AU5: =IF(SUMIFS('Detalhe Por UC'!$AB:$AB,'Detalhe Por UC'!$C:$C,'Infos Clientes'!$B5,'Detalhe Por UC'!$R:$R,'Infos Clientes'!AU$2)=0,"", SUMIFS('Detalhe Por UC'!$AB:$AB,'Detalhe Por UC'!$C:$C,'Infos Clientes'!$B5,'Detalhe Por UC'!$R:$R,'Infos Clientes'!AU$2) +SUMIFS('Detalhe Por UC'!$AC:$AC,'Detalhe Por UC'!$C:$C,'Infos Clientes'!$B5,'Detalhe Por UC'!$R:$R,'Infos Clientes'!AU$2))
B6: 10/113971-6 | C6: =ROW(F6) -> 6 | D6: IGREJA DO EVANGELHO QUADRANGULAR | E6: 319 | F6: 62.955.505/0156-01 | G6: pastora-regina@hotmail.com | H6: 10/113971-6 | I6: BT | J6: trifasico | K6: GIROSSOL II | M6: 0.25 | Q6: =IF(_xlfn.MINIFS('Detalhe Por UC'!R:R,'Detalhe Por UC'!C:C,B6,'Detalhe Por UC'!AD:AD,">"&0)=0,"",_xlfn.MINIFS('Detalhe Por UC'!R:R,'Detalhe Por UC'!C:C,B6,'Detalhe Por UC'!AD:AD,">"&0)) -> 45627 | R6: =IF(P6<>"ATIVO",0, IF(OR(Q6="",Q6=0,O6=0),O6, O6-ROUND((MAX('Detalhe Por UC'!R:R) -Q6)/(365/12),0))) -> 0 | T6: 236.08333 | U6: =IFERROR((SUMIFS(W6:CN6,$W$2:$CN$2,">"&$Q$1-365,$W$2:$CN$2,"<="&$Q$1)/COUNTIFS(W6:CN6,">="&0,$W$2:$CN$2,">"&$Q$1-365,$W$2:$CN$2,"<="&$Q$1)),"") -> 256.91667 | W6: 199 | X6: 189 | Y6: 230 | Z6: 213 | AA6: 329 | AB6: 259 | AC6: 203 | AD6: 211 | AE6: 218 | AF6: 177 | AG6: 244 | AH6: 218 | AI6: 278 | AJ6: =IF(SUMIFS('Detalhe Por UC'!$AB:$AB,'Detalhe Por UC'!$C:$C,'Infos Clientes'!$B6,'Detalhe Por UC'!$R:$R,'Infos Clientes'!AJ$2)=0,"", SUMIFS('Detalhe Por UC'!$AB:$AB,'Detalhe Por UC'!$C:$C,'Infos Clientes'!$B6,'Detalhe Por UC'!$R:$R,'Infos Clientes'!AJ$2) +SUMIFS('Detalhe Por UC'!$AC:$AC,'Detalhe Por UC'!$C:$C,'Infos Clientes'!$B6,'Detalhe Por UC'!$R:$R,'Infos Clientes'!AJ$2)) -> 253 | AK6: =IF(SUMIFS('Detalhe Por UC'!$AB:$AB,'Detalhe Por UC'!$C:$C,'Infos Clientes'!$B6,'Detalhe Por UC'!$R:$R,'Infos Clientes'!AK$2)=0,"", SUMIFS('Detalhe Por UC'!$AB:$AB,'Detalhe Por UC'!$C:$C,'Infos Clientes'!$B6,'Detalhe Por UC'!$R:$R,'Infos Clientes'!AK$2) +SUMIFS('Detalhe Por UC'!$AC:$AC,'Detalhe Por UC'!$C:$C,'Infos Clientes'!$B6,'Detalhe Por UC'!$R:$R,'Infos Clientes'!AK$2)) -> 324 | AL6: =IF(SUMIFS('Detalhe Por UC'!$AB:$AB,'Detalhe Por UC'!$C:$C,'Infos Clientes'!$B6,'Detalhe Por UC'!$R:$R,'Infos Clientes'!AL$2)=0,"", SUMIFS('Detalhe Por UC'!$AB:$AB,'Detalhe Por UC'!$C:$C,'Infos Clientes'!$B6,'Detalhe Por UC'!$R:$R,'Infos Clientes'!AL$2) +SUMIFS('Detalhe Por UC'!$AC:$AC,'Detalhe Por UC'!$C:$C,'Infos Clientes'!$B6,'Detalhe Por UC'!$R:$R,'Infos Clientes'!AL$2)) -> 394 | AM6: =IF(SUMIFS('Detalhe Por UC'!$AB:$AB,'Detalhe Por UC'!$C:$C,'Infos Clientes'!$B6,'Detalhe Por UC'!$R:$R,'Infos Clientes'!AM$2)=0,"", SUMIFS('Detalhe Por UC'!$AB:$AB,'Detalhe Por UC'!$C:$C,'Infos Clientes'!$B6,'Detalhe Por UC'!$R:$R,'Infos Clientes'!AM$2) +SUMIFS('Detalhe Por UC'!$AC:$AC,'Detalhe Por UC'!$C:$C,'Infos Clientes'!$B6,'Detalhe Por UC'!$R:$R,'Infos Clientes'!AM$2)) -> 290 | AN6: =IF(SUMIFS('Detalhe Por UC'!$AB:$AB,'Detalhe Por UC'!$C:$C,'Infos Clientes'!$B6,'Detalhe Por UC'!$R:$R,'Infos Clientes'!AN$2)=0,"", SUMIFS('Detalhe Por UC'!$AB:$AB,'Detalhe Por UC'!$C:$C,'Infos Clientes'!$B6,'Detalhe Por UC'!$R:$R,'Infos Clientes'!AN$2) +SUMIFS('Detalhe Por UC'!$AC:$AC,'Detalhe Por UC'!$C:$C,'Infos Clientes'!$B6,'Detalhe Por UC'!$R:$R,'Infos Clientes'!AN$2)) -> 226 | AO6: =IF(SUMIFS('Detalhe Por UC'!$AB:$AB,'Detalhe Por UC'!$C:$C,'Infos Clientes'!$B6,'Detalhe Por UC'!$R:$R,'Infos Clientes'!AO$2)=0,"", SUMIFS('Detalhe Por UC'!$AB:$AB,'Detalhe Por UC'!$C:$C,'Infos Clientes'!$B6,'Detalhe Por UC'!$R:$R,'Infos Clientes'!AO$2) +SUMIFS('Detalhe Por UC'!$AC:$AC,'Detalhe Por UC'!$C:$C,'Infos Clientes'!$B6,'Detalhe Por UC'!$R:$R,'Infos Clientes'!AO$2)) -> 202 | AP6: =IF(SUMIFS('Detalhe Por UC'!$AB:$AB,'Detalhe Por UC'!$C:$C,'Infos Clientes'!$B6,'Detalhe Por UC'!$R:$R,'Infos Clientes'!AP$2)=0,"", SUMIFS('Detalhe Por UC'!$AB:$AB,'Detalhe Por UC'!$C:$C,'Infos Clientes'!$B6,'Detalhe Por UC'!$R:$R,'Infos Clientes'!AP$2) +SUMIFS('Detalhe Por UC'!$AC:$AC,'Detalhe Por UC'!$C:$C,'Infos Clientes'!$B6,'Detalhe Por UC'!$R:$R,'Infos Clientes'!AP$2)) -> 197 | AQ6: =IF(SUMIFS('Detalhe Por UC'!$AB:$AB,'Detalhe Por UC'!$C:$C,'Infos Clientes'!$B6,'Detalhe Por UC'!$R:$R,'Infos Clientes'!AQ$2)=0,"", SUMIFS('Detalhe Por UC'!$AB:$AB,'Detalhe Por UC'!$C:$C,'Infos Clientes'!$B6,'Detalhe Por UC'!$R:$R,'Infos Clientes'!AQ$2) +SUMIFS('Detalhe Por UC'!$AC:$AC,'Detalhe Por UC'!$C:$C,'Infos Clientes'!$B6,'Detalhe Por UC'!$R:$R,'Infos Clientes'!AQ$2)) -> 184 | ... AU6: =IF(SUMIFS('Detalhe Por UC'!$AB:$AB,'Detalhe Por UC'!$C:$C,'Infos Clientes'!$B6,'Detalhe Por UC'!$R:$R,'Infos Clientes'!AU$2)=0,"", SUMIFS('Detalhe Por UC'!$AB:$AB,'Detalhe Por UC'!$C:$C,'Infos Clientes'!$B6,'Detalhe Por UC'!$R:$R,'Infos Clientes'!AU$2) +SUMIFS('Detalhe Por UC'!$AC:$AC,'Detalhe Por UC'!$C:$C,'Infos Clientes'!$B6,'Detalhe Por UC'!$R:$R,'Infos Clientes'!AU$2))
B7: 10/1184751-4 | C7: =ROW(F7) -> 7 | D7: IGREJA DO EVANGELHO QUADRANGULAR | E7: 319 | F7: 62.955.505/1490-47 | G7: monicadossantosfonseca@hotmail.com | H7: 10/1184751-4 | I7: BT | J7: trifasico | K7: GIROSSOL II | M7: 0.25 | Q7: =IF(_xlfn.MINIFS('Detalhe Por UC'!R:R,'Detalhe Por UC'!C:C,B7,'Detalhe Por UC'!AD:AD,">"&0)=0,"",_xlfn.MINIFS('Detalhe Por UC'!R:R,'Detalhe Por UC'!C:C,B7,'Detalhe Por UC'!AD:AD,">"&0)) -> 45627 | R7: =IF(P7<>"ATIVO",0, IF(OR(Q7="",Q7=0,O7=0),O7, O7-ROUND((MAX('Detalhe Por UC'!R:R) -Q7)/(365/12),0))) -> 0 | T7: 182.25 | U7: =IFERROR((SUMIFS(W7:CN7,$W$2:$CN$2,">"&$Q$1-365,$W$2:$CN$2,"<="&$Q$1)/COUNTIFS(W7:CN7,">="&0,$W$2:$CN$2,">"&$Q$1-365,$W$2:$CN$2,"<="&$Q$1)),"") -> 287.5 | W7: 216 | X7: 195 | Y7: 205 | Z7: 203 | AA7: 233 | AB7: 181 | AC7: 175 | AD7: 188 | AE7: 162 | AF7: 143 | AG7: 162 | AH7: 171 | AI7: 196 | AJ7: =IF(SUMIFS('Detalhe Por UC'!$AB:$AB,'Detalhe Por UC'!$C:$C,'Infos Clientes'!$B7,'Detalhe Por UC'!$R:$R,'Infos Clientes'!AJ$2)=0,"", SUMIFS('Detalhe Por UC'!$AB:$AB,'Detalhe Por UC'!$C:$C,'Infos Clientes'!$B7,'Detalhe Por UC'!$R:$R,'Infos Clientes'!AJ$2) +SUMIFS('Detalhe Por UC'!$AC:$AC,'Detalhe Por UC'!$C:$C,'Infos Clientes'!$B7,'Detalhe Por UC'!$R:$R,'Infos Clientes'!AJ$2)) -> 168 | AK7: =IF(SUMIFS('Detalhe Por UC'!$AB:$AB,'Detalhe Por UC'!$C:$C,'Infos Clientes'!$B7,'Detalhe Por UC'!$R:$R,'Infos Clientes'!AK$2)=0,"", SUMIFS('Detalhe Por UC'!$AB:$AB,'Detalhe Por UC'!$C:$C,'Infos Clientes'!$B7,'Detalhe Por UC'!$R:$R,'Infos Clientes'!AK$2) +SUMIFS('Detalhe Por UC'!$AC:$AC,'Detalhe Por UC'!$C:$C,'Infos Clientes'!$B7,'Detalhe Por UC'!$R:$R,'Infos Clientes'!AK$2)) -> 322 | AL7: =IF(SUMIFS('Detalhe Por UC'!$AB:$AB,'Detalhe Por UC'!$C:$C,'Infos Clientes'!$B7,'Detalhe Por UC'!$R:$R,'Infos Clientes'!AL$2)=0,"", SUMIFS('Detalhe Por UC'!$AB:$AB,'Detalhe Por UC'!$C:$C,'Infos Clientes'!$B7,'Detalhe Por UC'!$R:$R,'Infos Clientes'!AL$2) +SUMIFS('Detalhe Por UC'!$AC:$AC,'Detalhe Por UC'!$C:$C,'Infos Clientes'!$B7,'Detalhe Por UC'!$R:$R,'Infos Clientes'!AL$2)) -> 371 | AM7: =IF(SUMIFS('Detalhe Por UC'!$AB:$AB,'Detalhe Por UC'!$C:$C,'Infos Clientes'!$B7,'Detalhe Por UC'!$R:$R,'Infos Clientes'!AM$2)=0,"", SUMIFS('Detalhe Por UC'!$AB:$AB,'Detalhe Por UC'!$C:$C,'Infos Clientes'!$B7,'Detalhe Por UC'!$R:$R,'Infos Clientes'!AM$2) +SUMIFS('Detalhe Por UC'!$AC:$AC,'Detalhe Por UC'!$C:$C,'Infos Clientes'!$B7,'Detalhe Por UC'!$R:$R,'Infos Clientes'!AM$2)) -> 317 | AN7: =IF(SUMIFS('Detalhe Por UC'!$AB:$AB,'Detalhe Por UC'!$C:$C,'Infos Clientes'!$B7,'Detalhe Por UC'!$R:$R,'Infos Clientes'!AN$2)=0,"", SUMIFS('Detalhe Por UC'!$AB:$AB,'Detalhe Por UC'!$C:$C,'Infos Clientes'!$B7,'Detalhe Por UC'!$R:$R,'Infos Clientes'!AN$2) +SUMIFS('Detalhe Por UC'!$AC:$AC,'Detalhe Por UC'!$C:$C,'Infos Clientes'!$B7,'Detalhe Por UC'!$R:$R,'Infos Clientes'!AN$2)) -> 293 | AO7: =IF(SUMIFS('Detalhe Por UC'!$AB:$AB,'Detalhe Por UC'!$C:$C,'Infos Clientes'!$B7,'Detalhe Por UC'!$R:$R,'Infos Clientes'!AO$2)=0,"", SUMIFS('Detalhe Por UC'!$AB:$AB,'Detalhe Por UC'!$C:$C,'Infos Clientes'!$B7,'Detalhe Por UC'!$R:$R,'Infos Clientes'!AO$2) +SUMIFS('Detalhe Por UC'!$AC:$AC,'Detalhe Por UC'!$C:$C,'Infos Clientes'!$B7,'Detalhe Por UC'!$R:$R,'Infos Clientes'!AO$2)) -> 323 | AP7: =IF(SUMIFS('Detalhe Por UC'!$AB:$AB,'Detalhe Por UC'!$C:$C,'Infos Clientes'!$B7,'Detalhe Por UC'!$R:$R,'Infos Clientes'!AP$2)=0,"", SUMIFS('Detalhe Por UC'!$AB:$AB,'Detalhe Por UC'!$C:$C,'Infos Clientes'!$B7,'Detalhe Por UC'!$R:$R,'Infos Clientes'!AP$2) +SUMIFS('Detalhe Por UC'!$AC:$AC,'Detalhe Por UC'!$C:$C,'Infos Clientes'!$B7,'Detalhe Por UC'!$R:$R,'Infos Clientes'!AP$2)) -> 292 | AQ7: =IF(SUMIFS('Detalhe Por UC'!$AB:$AB,'Detalhe Por UC'!$C:$C,'Infos Clientes'!$B7,'Detalhe Por UC'!$R:$R,'Infos Clientes'!AQ$2)=0,"", SUMIFS('Detalhe Por UC'!$AB:$AB,'Detalhe Por UC'!$C:$C,'Infos Clientes'!$B7,'Detalhe Por UC'!$R:$R,'Infos Clientes'!AQ$2) +SUMIFS('Detalhe Por UC'!$AC:$AC,'Detalhe Por UC'!$C:$C,'Infos Clientes'!$B7,'Detalhe Por UC'!$R:$R,'Infos Clientes'!AQ$2)) -> 298 | ... AU7: =IF(SUMIFS('Detalhe Por UC'!$AB:$AB,'Detalhe Por UC'!$C:$C,'Infos Clientes'!$B7,'Detalhe Por UC'!$R:$R,'Infos Clientes'!AU$2)=0,"", SUMIFS('Detalhe Por UC'!$AB:$AB,'Detalhe Por UC'!$C:$C,'Infos Clientes'!$B7,'Detalhe Por UC'!$R:$R,'Infos Clientes'!AU$2) +SUMIFS('Detalhe Por UC'!$AC:$AC,'Detalhe Por UC'!$C:$C,'Infos Clientes'!$B7,'Detalhe Por UC'!$R:$R,'Infos Clientes'!AU$2))
B8: 10/135237-6 | C8: =ROW(F8) -> 8 | D8: IGREJA DO EVANGELHO QUADRANGULAR | E8: 351 | F8: 62.955.505/0800-98 | G8: igrejaquadrangularmaracaju1@hotmail.com | H8: 10/135237-6 | I8: BT | J8: trifasico | K8: GIROSSOL II | M8: 0.25 | Q8: =IF(_xlfn.MINIFS('Detalhe Por UC'!R:R,'Detalhe Por UC'!C:C,B8,'Detalhe Por UC'!AD:AD,">"&0)=0,"",_xlfn.MINIFS('Detalhe Por UC'!R:R,'Detalhe Por UC'!C:C,B8,'Detalhe Por UC'!AD:AD,">"&0)) -> 45627 | R8: =IF(P8<>"ATIVO",0, IF(OR(Q8="",Q8=0,O8=0),O8, O8-ROUND((MAX('Detalhe Por UC'!R:R) -Q8)/(365/12),0))) -> 0 | T8: 134.36364 | U8: =IFERROR((SUMIFS(W8:CN8,$W$2:$CN$2,">"&$Q$1-365,$W$2:$CN$2,"<="&$Q$1)/COUNTIFS(W8:CN8,">="&0,$W$2:$CN$2,">"&$Q$1-365,$W$2:$CN$2,"<="&$Q$1)),"") -> 148.125 | W8: 130 | X8: 124 | Y8: 151 | Z8: 183 | AA8: 156 | AB8: 184 | AC8: 100 | AD8: 90 | AE8: 103 | AF8: 113 | AG8: 148 | AH8: 112 | AI8: 138 | AJ8: =IF(SUMIFS('Detalhe Por UC'!$AB:$AB,'Detalhe Por UC'!$C:$C,'Infos Clientes'!$B8,'Detalhe Por UC'!$R:$R,'Infos Clientes'!AJ$2)=0,"", SUMIFS('Detalhe Por UC'!$AB:$AB,'Detalhe Por UC'!$C:$C,'Infos Clientes'!$B8,'Detalhe Por UC'!$R:$R,'Infos Clientes'!AJ$2) +SUMIFS('Detalhe Por UC'!$AC:$AC,'Detalhe Por UC'!$C:$C,'Infos Clientes'!$B8,'Detalhe Por UC'!$R:$R,'Infos Clientes'!AJ$2)) | AK8: =IF(SUMIFS('Detalhe Por UC'!$AB:$AB,'Detalhe Por UC'!$C:$C,'Infos Clientes'!$B8,'Detalhe Por UC'!$R:$R,'Infos Clientes'!AK$2)=0,"", SUMIFS('Detalhe Por UC'!$AB:$AB,'Detalhe Por UC'!$C:$C,'Infos Clientes'!$B8,'Detalhe Por UC'!$R:$R,'Infos Clientes'!AK$2) +SUMIFS('Detalhe Por UC'!$AC:$AC,'Detalhe Por UC'!$C:$C,'Infos Clientes'!$B8,'Detalhe Por UC'!$R:$R,'Infos Clientes'!AK$2)) -> 159 | AL8: =IF(SUMIFS('Detalhe Por UC'!$AB:$AB,'Detalhe Por UC'!$C:$C,'Infos Clientes'!$B8,'Detalhe Por UC'!$R:$R,'Infos Clientes'!AL$2)=0,"", SUMIFS('Detalhe Por UC'!$AB:$AB,'Detalhe Por UC'!$C:$C,'Infos Clientes'!$B8,'Detalhe Por UC'!$R:$R,'Infos Clientes'!AL$2) +SUMIFS('Detalhe Por UC'!$AC:$AC,'Detalhe Por UC'!$C:$C,'Infos Clientes'!$B8,'Detalhe Por UC'!$R:$R,'Infos Clientes'!AL$2)) -> 197 | AM8: =IF(SUMIFS('Detalhe Por UC'!$AB:$AB,'Detalhe Por UC'!$C:$C,'Infos Clientes'!$B8,'Detalhe Por UC'!$R:$R,'Infos Clientes'!AM$2)=0,"", SUMIFS('Detalhe Por UC'!$AB:$AB,'Detalhe Por UC'!$C:$C,'Infos Clientes'!$B8,'Detalhe Por UC'!$R:$R,'Infos Clientes'!AM$2) +SUMIFS('Detalhe Por UC'!$AC:$AC,'Detalhe Por UC'!$C:$C,'Infos Clientes'!$B8,'Detalhe Por UC'!$R:$R,'Infos Clientes'!AM$2)) -> 157 | AN8: =IF(SUMIFS('Detalhe Por UC'!$AB:$AB,'Detalhe Por UC'!$C:$C,'Infos Clientes'!$B8,'Detalhe Por UC'!$R:$R,'Infos Clientes'!AN$2)=0,"", SUMIFS('Detalhe Por UC'!$AB:$AB,'Detalhe Por UC'!$C:$C,'Infos Clientes'!$B8,'Detalhe Por UC'!$R:$R,'Infos Clientes'!AN$2) +SUMIFS('Detalhe Por UC'!$AC:$AC,'Detalhe Por UC'!$C:$C,'Infos Clientes'!$B8,'Detalhe Por UC'!$R:$R,'Infos Clientes'!AN$2)) -> 106 | AO8: =IF(SUMIFS('Detalhe Por UC'!$AB:$AB,'Detalhe Por UC'!$C:$C,'Infos Clientes'!$B8,'Detalhe Por UC'!$R:$R,'Infos Clientes'!AO$2)=0,"", SUMIFS('Detalhe Por UC'!$AB:$AB,'Detalhe Por UC'!$C:$C,'Infos Clientes'!$B8,'Detalhe Por UC'!$R:$R,'Infos Clientes'!AO$2) +SUMIFS('Detalhe Por UC'!$AC:$AC,'Detalhe Por UC'!$C:$C,'Infos Clientes'!$B8,'Detalhe Por UC'!$R:$R,'Infos Clientes'!AO$2)) | AP8: =IF(SUMIFS('Detalhe Por UC'!$AB:$AB,'Detalhe Por UC'!$C:$C,'Infos Clientes'!$B8,'Detalhe Por UC'!$R:$R,'Infos Clientes'!AP$2)=0,"", SUMIFS('Detalhe Por UC'!$AB:$AB,'Detalhe Por UC'!$C:$C,'Infos Clientes'!$B8,'Detalhe Por UC'!$R:$R,'Infos Clientes'!AP$2) +SUMIFS('Detalhe Por UC'!$AC:$AC,'Detalhe Por UC'!$C:$C,'Infos Clientes'!$B8,'Detalhe Por UC'!$R:$R,'Infos Clientes'!AP$2)) | AQ8: =IF(SUMIFS('Detalhe Por UC'!$AB:$AB,'Detalhe Por UC'!$C:$C,'Infos Clientes'!$B8,'Detalhe Por UC'!$R:$R,'Infos Clientes'!AQ$2)=0,"", SUMIFS('Detalhe Por UC'!$AB:$AB,'Detalhe Por UC'!$C:$C,'Infos Clientes'!$B8,'Detalhe Por UC'!$R:$R,'Infos Clientes'!AQ$2) +SUMIFS('Detalhe Por UC'!$AC:$AC,'Detalhe Por UC'!$C:$C,'Infos Clientes'!$B8,'Detalhe Por UC'!$R:$R,'Infos Clientes'!AQ$2)) -> 100 | ... AU8: =IF(SUMIFS('Detalhe Por UC'!$AB:$AB,'Detalhe Por UC'!$C:$C,'Infos Clientes'!$B8,'Detalhe Por UC'!$R:$R,'Infos Clientes'!AU$2)=0,"", SUMIFS('Detalhe Por UC'!$AB:$AB,'Detalhe Por UC'!$C:$C,'Infos Clientes'!$B8,'Detalhe Por UC'!$R:$R,'Infos Clientes'!AU$2) +SUMIFS('Detalhe Por UC'!$AC:$AC,'Detalhe Por UC'!$C:$C,'Infos Clientes'!$B8,'Detalhe Por UC'!$R:$R,'Infos Clientes'!AU$2))
B9: 10/1548741-6 | C9: =ROW(F9) -> 9 | D9: IGREJA DO EVANGELHO QUADRANGULAR | E9: 349 | F9: 62.955.505/0847-51 | G9: neivaldocastro@hotmail.com | H9: 10/1548741-6 | I9: BT | J9: monofasico | K9: GIROSSOL II | M9: 0.25 | Q9: =IF(_xlfn.MINIFS('Detalhe Por UC'!R:R,'Detalhe Por UC'!C:C,B9,'Detalhe Por UC'!AD:AD,">"&0)=0,"",_xlfn.MINIFS('Detalhe Por UC'!R:R,'Detalhe Por UC'!C:C,B9,'Detalhe Por UC'!AD:AD,">"&0)) -> 45627 | R9: =IF(P9<>"ATIVO",0, IF(OR(Q9="",Q9=0,O9=0),O9, O9-ROUND((MAX('Detalhe Por UC'!R:R) -Q9)/(365/12),0))) -> 0 | T9: 156.25 | U9: =IFERROR((SUMIFS(W9:CN9,$W$2:$CN$2,">"&$Q$1-365,$W$2:$CN$2,"<="&$Q$1)/COUNTIFS(W9:CN9,">="&0,$W$2:$CN$2,">"&$Q$1-365,$W$2:$CN$2,"<="&$Q$1)),"") -> 152.91667 | W9: 179 | X9: 221 | Y9: 202 | Z9: 159 | AA9: 173 | AB9: 154 | AC9: 151 | AD9: 144 | AE9: 136 | AF9: 128 | AG9: 155 | AH9: 146 | AI9: 156 | AJ9: =IF(SUMIFS('Detalhe Por UC'!$AB:$AB,'Detalhe Por UC'!$C:$C,'Infos Clientes'!$B9,'Detalhe Por UC'!$R:$R,'Infos Clientes'!AJ$2)=0,"", SUMIFS('Detalhe Por UC'!$AB:$AB,'Detalhe Por UC'!$C:$C,'Infos Clientes'!$B9,'Detalhe Por UC'!$R:$R,'Infos Clientes'!AJ$2) +SUMIFS('Detalhe Por UC'!$AC:$AC,'Detalhe Por UC'!$C:$C,'Infos Clientes'!$B9,'Detalhe Por UC'!$R:$R,'Infos Clientes'!AJ$2)) -> 171 | AK9: =IF(SUMIFS('Detalhe Por UC'!$AB:$AB,'Detalhe Por UC'!$C:$C,'Infos Clientes'!$B9,'Detalhe Por UC'!$R:$R,'Infos Clientes'!AK$2)=0,"", SUMIFS('Detalhe Por UC'!$AB:$AB,'Detalhe Por UC'!$C:$C,'Infos Clientes'!$B9,'Detalhe Por UC'!$R:$R,'Infos Clientes'!AK$2) +SUMIFS('Detalhe Por UC'!$AC:$AC,'Detalhe Por UC'!$C:$C,'Infos Clientes'!$B9,'Detalhe Por UC'!$R:$R,'Infos Clientes'!AK$2)) -> 172 | AL9: =IF(SUMIFS('Detalhe Por UC'!$AB:$AB,'Detalhe Por UC'!$C:$C,'Infos Clientes'!$B9,'Detalhe Por UC'!$R:$R,'Infos Clientes'!AL$2)=0,"", SUMIFS('Detalhe Por UC'!$AB:$AB,'Detalhe Por UC'!$C:$C,'Infos Clientes'!$B9,'Detalhe Por UC'!$R:$R,'Infos Clientes'!AL$2) +SUMIFS('Detalhe Por UC'!$AC:$AC,'Detalhe Por UC'!$C:$C,'Infos Clientes'!$B9,'Detalhe Por UC'!$R:$R,'Infos Clientes'!AL$2)) -> 153 | AM9: =IF(SUMIFS('Detalhe Por UC'!$AB:$AB,'Detalhe Por UC'!$C:$C,'Infos Clientes'!$B9,'Detalhe Por UC'!$R:$R,'Infos Clientes'!AM$2)=0,"", SUMIFS('Detalhe Por UC'!$AB:$AB,'Detalhe Por UC'!$C:$C,'Infos Clientes'!$B9,'Detalhe Por UC'!$R:$R,'Infos Clientes'!AM$2) +SUMIFS('Detalhe Por UC'!$AC:$AC,'Detalhe Por UC'!$C:$C,'Infos Clientes'!$B9,'Detalhe Por UC'!$R:$R,'Infos Clientes'!AM$2)) -> 179 | AN9: =IF(SUMIFS('Detalhe Por UC'!$AB:$AB,'Detalhe Por UC'!$C:$C,'Infos Clientes'!$B9,'Detalhe Por UC'!$R:$R,'Infos Clientes'!AN$2)=0,"", SUMIFS('Detalhe Por UC'!$AB:$AB,'Detalhe Por UC'!$C:$C,'Infos Clientes'!$B9,'Detalhe Por UC'!$R:$R,'Infos Clientes'!AN$2) +SUMIFS('Detalhe Por UC'!$AC:$AC,'Detalhe Por UC'!$C:$C,'Infos Clientes'!$B9,'Detalhe Por UC'!$R:$R,'Infos Clientes'!AN$2)) -> 153 | AO9: =IF(SUMIFS('Detalhe Por UC'!$AB:$AB,'Detalhe Por UC'!$C:$C,'Infos Clientes'!$B9,'Detalhe Por UC'!$R:$R,'Infos Clientes'!AO$2)=0,"", SUMIFS('Detalhe Por UC'!$AB:$AB,'Detalhe Por UC'!$C:$C,'Infos Clientes'!$B9,'Detalhe Por UC'!$R:$R,'Infos Clientes'!AO$2) +SUMIFS('Detalhe Por UC'!$AC:$AC,'Detalhe Por UC'!$C:$C,'Infos Clientes'!$B9,'Detalhe Por UC'!$R:$R,'Infos Clientes'!AO$2)) -> 126 | AP9: =IF(SUMIFS('Detalhe Por UC'!$AB:$AB,'Detalhe Por UC'!$C:$C,'Infos Clientes'!$B9,'Detalhe Por UC'!$R:$R,'Infos Clientes'!AP$2)=0,"", SUMIFS('Detalhe Por UC'!$AB:$AB,'Detalhe Por UC'!$C:$C,'Infos Clientes'!$B9,'Detalhe Por UC'!$R:$R,'Infos Clientes'!AP$2) +SUMIFS('Detalhe Por UC'!$AC:$AC,'Detalhe Por UC'!$C:$C,'Infos Clientes'!$B9,'Detalhe Por UC'!$R:$R,'Infos Clientes'!AP$2)) -> 116 | AQ9: =IF(SUMIFS('Detalhe Por UC'!$AB:$AB,'Detalhe Por UC'!$C:$C,'Infos Clientes'!$B9,'Detalhe Por UC'!$R:$R,'Infos Clientes'!AQ$2)=0,"", SUMIFS('Detalhe Por UC'!$AB:$AB,'Detalhe Por UC'!$C:$C,'Infos Clientes'!$B9,'Detalhe Por UC'!$R:$R,'Infos Clientes'!AQ$2) +SUMIFS('Detalhe Por UC'!$AC:$AC,'Detalhe Por UC'!$C:$C,'Infos Clientes'!$B9,'Detalhe Por UC'!$R:$R,'Infos Clientes'!AQ$2)) -> 98 | ... AU9: =IF(SUMIFS('Detalhe Por UC'!$AB:$AB,'Detalhe Por UC'!$C:$C,'Infos Clientes'!$B9,'Detalhe Por UC'!$R:$R,'Infos Clientes'!AU$2)=0,"", SUMIFS('Detalhe Por UC'!$AB:$AB,'Detalhe Por UC'!$C:$C,'Infos Clientes'!$B9,'Detalhe Por UC'!$R:$R,'Infos Clientes'!AU$2) +SUMIFS('Detalhe Por UC'!$AC:$AC,'Detalhe Por UC'!$C:$C,'Infos Clientes'!$B9,'Detalhe Por UC'!$R:$R,'Infos Clientes'!AU$2))
B10: 10/156956-5 | C10: =ROW(F10) -> 10 | D10: IGREJA DO EVANGELHO QUADRANGULAR | E10: 994 | F10: 62.955.505/0153-50 | G10: quadrangular994@gmail.com | H10: 10/156956-5 | I10: BT | J10: trifasico | K10: GIROSSOL II | M10: 0.25 | Q10: =IF(_xlfn.MINIFS('Detalhe Por UC'!R:R,'Detalhe Por UC'!C:C,B10,'Detalhe Por UC'!AD:AD,">"&0)=0,"",_xlfn.MINIFS('Detalhe Por UC'!R:R,'Detalhe Por UC'!C:C,B10,'Detalhe Por UC'!AD:AD,">"&0)) -> 45627 | R10: =IF(P10<>"ATIVO",0, IF(OR(Q10="",Q10=0,O10=0),O10, O10-ROUND((MAX('Detalhe Por UC'!R:R) -Q10)/(365/12),0))) -> 0 | T10: 362.41667 | U10: =IFERROR((SUMIFS(W10:CN10,$W$2:$CN$2,">"&$Q$1-365,$W$2:$CN$2,"<="&$Q$1)/COUNTIFS(W10:CN10,">="&0,$W$2:$CN$2,">"&$Q$1-365,$W$2:$CN$2,"<="&$Q$1)),"") -> 321.16667 | W10: 393 | X10: 453 | Y10: 419 | Z10: 472 | AA10: 554 | AB10: 456 | AC10: 201 | AD10: 168 | AE10: 172 | AF10: 305 | AG10: 370 | AH10: 345 | AI10: 491 | AJ10: =IF(SUMIFS('Detalhe Por UC'!$AB:$AB,'Detalhe Por UC'!$C:$C,'Infos Clientes'!$B10,'Detalhe Por UC'!$R:$R,'Infos Clientes'!AJ$2)=0,"", SUMIFS('Detalhe Por UC'!$AB:$AB,'Detalhe Por UC'!$C:$C,'Infos Clientes'!$B10,'Detalhe Por UC'!$R:$R,'Infos Clientes'!AJ$2) +SUMIFS('Detalhe Por UC'!$AC:$AC,'Detalhe Por UC'!$C:$C,'Infos Clientes'!$B10,'Detalhe Por UC'!$R:$R,'Infos Clientes'!AJ$2)) -> 396 | AK10: =IF(SUMIFS('Detalhe Por UC'!$AB:$AB,'Detalhe Por UC'!$C:$C,'Infos Clientes'!$B10,'Detalhe Por UC'!$R:$R,'Infos Clientes'!AK$2)=0,"", SUMIFS('Detalhe Por UC'!$AB:$AB,'Detalhe Por UC'!$C:$C,'Infos Clientes'!$B10,'Detalhe Por UC'!$R:$R,'Infos Clientes'!AK$2) +SUMIFS('Detalhe Por UC'!$AC:$AC,'Detalhe Por UC'!$C:$C,'Infos Clientes'!$B10,'Detalhe Por UC'!$R:$R,'Infos Clientes'!AK$2)) -> 490 | AL10: =IF(SUMIFS('Detalhe Por UC'!$AB:$AB,'Detalhe Por UC'!$C:$C,'Infos Clientes'!$B10,'Detalhe Por UC'!$R:$R,'Infos Clientes'!AL$2)=0,"", SUMIFS('Detalhe Por UC'!$AB:$AB,'Detalhe Por UC'!$C:$C,'Infos Clientes'!$B10,'Detalhe Por UC'!$R:$R,'Infos Clientes'!AL$2) +SUMIFS('Detalhe Por UC'!$AC:$AC,'Detalhe Por UC'!$C:$C,'Infos Clientes'!$B10,'Detalhe Por UC'!$R:$R,'Infos Clientes'!AL$2)) -> 489 | AM10: =IF(SUMIFS('Detalhe Por UC'!$AB:$AB,'Detalhe Por UC'!$C:$C,'Infos Clientes'!$B10,'Detalhe Por UC'!$R:$R,'Infos Clientes'!AM$2)=0,"", SUMIFS('Detalhe Por UC'!$AB:$AB,'Detalhe Por UC'!$C:$C,'Infos Clientes'!$B10,'Detalhe Por UC'!$R:$R,'Infos Clientes'!AM$2) +SUMIFS('Detalhe Por UC'!$AC:$AC,'Detalhe Por UC'!$C:$C,'Infos Clientes'!$B10,'Detalhe Por UC'!$R:$R,'Infos Clientes'!AM$2)) -> 312 | AN10: =IF(SUMIFS('Detalhe Por UC'!$AB:$AB,'Detalhe Por UC'!$C:$C,'Infos Clientes'!$B10,'Detalhe Por UC'!$R:$R,'Infos Clientes'!AN$2)=0,"", SUMIFS('Detalhe Por UC'!$AB:$AB,'Detalhe Por UC'!$C:$C,'Infos Clientes'!$B10,'Detalhe Por UC'!$R:$R,'Infos Clientes'!AN$2) +SUMIFS('Detalhe Por UC'!$AC:$AC,'Detalhe Por UC'!$C:$C,'Infos Clientes'!$B10,'Detalhe Por UC'!$R:$R,'Infos Clientes'!AN$2)) -> 276 | AO10: =IF(SUMIFS('Detalhe Por UC'!$AB:$AB,'Detalhe Por UC'!$C:$C,'Infos Clientes'!$B10,'Detalhe Por UC'!$R:$R,'Infos Clientes'!AO$2)=0,"", SUMIFS('Detalhe Por UC'!$AB:$AB,'Detalhe Por UC'!$C:$C,'Infos Clientes'!$B10,'Detalhe Por UC'!$R:$R,'Infos Clientes'!AO$2) +SUMIFS('Detalhe Por UC'!$AC:$AC,'Detalhe Por UC'!$C:$C,'Infos Clientes'!$B10,'Detalhe Por UC'!$R:$R,'Infos Clientes'!AO$2)) -> 189 | AP10: =IF(SUMIFS('Detalhe Por UC'!$AB:$AB,'Detalhe Por UC'!$C:$C,'Infos Clientes'!$B10,'Detalhe Por UC'!$R:$R,'Infos Clientes'!AP$2)=0,"", SUMIFS('Detalhe Por UC'!$AB:$AB,'Detalhe Por UC'!$C:$C,'Infos Clientes'!$B10,'Detalhe Por UC'!$R:$R,'Infos Clientes'!AP$2) +SUMIFS('Detalhe Por UC'!$AC:$AC,'Detalhe Por UC'!$C:$C,'Infos Clientes'!$B10,'Detalhe Por UC'!$R:$R,'Infos Clientes'!AP$2)) -> 154 | AQ10: =IF(SUMIFS('Detalhe Por UC'!$AB:$AB,'Detalhe Por UC'!$C:$C,'Infos Clientes'!$B10,'Detalhe Por UC'!$R:$R,'Infos Clientes'!AQ$2)=0,"", SUMIFS('Detalhe Por UC'!$AB:$AB,'Detalhe Por UC'!$C:$C,'Infos Clientes'!$B10,'Detalhe Por UC'!$R:$R,'Infos Clientes'!AQ$2) +SUMIFS('Detalhe Por UC'!$AC:$AC,'Detalhe Por UC'!$C:$C,'Infos Clientes'!$B10,'Detalhe Por UC'!$R:$R,'Infos Clientes'!AQ$2)) -> 200 | ... AU10: =IF(SUMIFS('Detalhe Por UC'!$AB:$AB,'Detalhe Por UC'!$C:$C,'Infos Clientes'!$B10,'Detalhe Por UC'!$R:$R,'Infos Clientes'!AU$2)=0,"", SUMIFS('Detalhe Por UC'!$AB:$AB,'Detalhe Por UC'!$C:$C,'Infos Clientes'!$B10,'Detalhe Por UC'!$R:$R,'Infos Clientes'!AU$2) +SUMIFS('Detalhe Por UC'!$AC:$AC,'Detalhe Por UC'!$C:$C,'Infos Clientes'!$B10,'Detalhe Por UC'!$R:$R,'Infos Clientes'!AU$2))
B11: 10/2794432-1 | C11: =ROW(F11) -> 11 | D11: IGREJA DO EVANGELHO QUADRANGULAR | E11: 306 | F11: 62.955.505/0151-99 | G11: carlaestreito@hotmail.com | H11: 10/2794432-1 | I11: BT | J11: trifasico | K11: GIROSSOL II | M11: 0.25 | Q11: =IF(_xlfn.MINIFS('Detalhe Por UC'!R:R,'Detalhe Por UC'!C:C,B11,'Detalhe Por UC'!AD:AD,">"&0)=0,"",_xlfn.MINIFS('Detalhe Por UC'!R:R,'Detalhe Por UC'!C:C,B11,'Detalhe Por UC'!AD:AD,">"&0)) -> 45658 | R11: =IF(P11<>"ATIVO",0, IF(OR(Q11="",Q11=0,O11=0),O11, O11-ROUND((MAX('Detalhe Por UC'!R:R) -Q11)/(365/12),0))) -> 0 | T11: 286.5 | U11: =IFERROR((SUMIFS(W11:CN11,$W$2:$CN$2,">"&$Q$1-365,$W$2:$CN$2,"<="&$Q$1)/COUNTIFS(W11:CN11,">="&0,$W$2:$CN$2,">"&$Q$1-365,$W$2:$CN$2,"<="&$Q$1)),"") -> 494.83333 | W11: 0 | X11: 0 | Y11: 0 | Z11: 132 | AA11: 131 | AB11: 160 | AC11: 136 | AD11: 88 | AE11: 221 | AF11: 390 | AG11: 551 | AH11: 533 | AI11: 601 | AJ11: =IF(SUMIFS('Detalhe Por UC'!$AB:$AB,'Detalhe Por UC'!$C:$C,'Infos Clientes'!$B11,'Detalhe Por UC'!$R:$R,'Infos Clientes'!AJ$2)=0,"", SUMIFS('Detalhe Por UC'!$AB:$AB,'Detalhe Por UC'!$C:$C,'Infos Clientes'!$B11,'Detalhe Por UC'!$R:$R,'Infos Clientes'!AJ$2) +SUMIFS('Detalhe Por UC'!$AC:$AC,'Detalhe Por UC'!$C:$C,'Infos Clientes'!$B11,'Detalhe Por UC'!$R:$R,'Infos Clientes'!AJ$2)) -> 495 | AK11: =IF(SUMIFS('Detalhe Por UC'!$AB:$AB,'Detalhe Por UC'!$C:$C,'Infos Clientes'!$B11,'Detalhe Por UC'!$R:$R,'Infos Clientes'!AK$2)=0,"", SUMIFS('Detalhe Por UC'!$AB:$AB,'Detalhe Por UC'!$C:$C,'Infos Clientes'!$B11,'Detalhe Por UC'!$R:$R,'Infos Clientes'!AK$2) +SUMIFS('Detalhe Por UC'!$AC:$AC,'Detalhe Por UC'!$C:$C,'Infos Clientes'!$B11,'Detalhe Por UC'!$R:$R,'Infos Clientes'!AK$2)) -> 479 | AL11: =IF(SUMIFS('Detalhe Por UC'!$AB:$AB,'Detalhe Por UC'!$C:$C,'Infos Clientes'!$B11,'Detalhe Por UC'!$R:$R,'Infos Clientes'!AL$2)=0,"", SUMIFS('Detalhe Por UC'!$AB:$AB,'Detalhe Por UC'!$C:$C,'Infos Clientes'!$B11,'Detalhe Por UC'!$R:$R,'Infos Clientes'!AL$2) +SUMIFS('Detalhe Por UC'!$AC:$AC,'Detalhe Por UC'!$C:$C,'Infos Clientes'!$B11,'Detalhe Por UC'!$R:$R,'Infos Clientes'!AL$2)) -> 713 | AM11: =IF(SUMIFS('Detalhe Por UC'!$AB:$AB,'Detalhe Por UC'!$C:$C,'Infos Clientes'!$B11,'Detalhe Por UC'!$R:$R,'Infos Clientes'!AM$2)=0,"", SUMIFS('Detalhe Por UC'!$AB:$AB,'Detalhe Por UC'!$C:$C,'Infos Clientes'!$B11,'Detalhe Por UC'!$R:$R,'Infos Clientes'!AM$2) +SUMIFS('Detalhe Por UC'!$AC:$AC,'Detalhe Por UC'!$C:$C,'Infos Clientes'!$B11,'Detalhe Por UC'!$R:$R,'Infos Clientes'!AM$2)) -> 385 | AN11: =IF(SUMIFS('Detalhe Por UC'!$AB:$AB,'Detalhe Por UC'!$C:$C,'Infos Clientes'!$B11,'Detalhe Por UC'!$R:$R,'Infos Clientes'!AN$2)=0,"", SUMIFS('Detalhe Por UC'!$AB:$AB,'Detalhe Por UC'!$C:$C,'Infos Clientes'!$B11,'Detalhe Por UC'!$R:$R,'Infos Clientes'!AN$2) +SUMIFS('Detalhe Por UC'!$AC:$AC,'Detalhe Por UC'!$C:$C,'Infos Clientes'!$B11,'Detalhe Por UC'!$R:$R,'Infos Clientes'!AN$2)) -> 484 | AO11: =IF(SUMIFS('Detalhe Por UC'!$AB:$AB,'Detalhe Por UC'!$C:$C,'Infos Clientes'!$B11,'Detalhe Por UC'!$R:$R,'Infos Clientes'!AO$2)=0,"", SUMIFS('Detalhe Por UC'!$AB:$AB,'Detalhe Por UC'!$C:$C,'Infos Clientes'!$B11,'Detalhe Por UC'!$R:$R,'Infos Clientes'!AO$2) +SUMIFS('Detalhe Por UC'!$AC:$AC,'Detalhe Por UC'!$C:$C,'Infos Clientes'!$B11,'Detalhe Por UC'!$R:$R,'Infos Clientes'!AO$2)) -> 592 | AP11: =IF(SUMIFS('Detalhe Por UC'!$AB:$AB,'Detalhe Por UC'!$C:$C,'Infos Clientes'!$B11,'Detalhe Por UC'!$R:$R,'Infos Clientes'!AP$2)=0,"", SUMIFS('Detalhe Por UC'!$AB:$AB,'Detalhe Por UC'!$C:$C,'Infos Clientes'!$B11,'Detalhe Por UC'!$R:$R,'Infos Clientes'!AP$2) +SUMIFS('Detalhe Por UC'!$AC:$AC,'Detalhe Por UC'!$C:$C,'Infos Clientes'!$B11,'Detalhe Por UC'!$R:$R,'Infos Clientes'!AP$2)) -> 299 | AQ11: =IF(SUMIFS('Detalhe Por UC'!$AB:$AB,'Detalhe Por UC'!$C:$C,'Infos Clientes'!$B11,'Detalhe Por UC'!$R:$R,'Infos Clientes'!AQ$2)=0,"", SUMIFS('Detalhe Por UC'!$AB:$AB,'Detalhe Por UC'!$C:$C,'Infos Clientes'!$B11,'Detalhe Por UC'!$R:$R,'Infos Clientes'!AQ$2) +SUMIFS('Detalhe Por UC'!$AC:$AC,'Detalhe Por UC'!$C:$C,'Infos Clientes'!$B11,'Detalhe Por UC'!$R:$R,'Infos Clientes'!AQ$2)) -> 491 | ... AU11: =IF(SUMIFS('Detalhe Por UC'!$AB:$AB,'Detalhe Por UC'!$C:$C,'Infos Clientes'!$B11,'Detalhe Por UC'!$R:$R,'Infos Clientes'!AU$2)=0,"", SUMIFS('Detalhe Por UC'!$AB:$AB,'Detalhe Por UC'!$C:$C,'Infos Clientes'!$B11,'Detalhe Por UC'!$R:$R,'Infos Clientes'!AU$2) +SUMIFS('Detalhe Por UC'!$AC:$AC,'Detalhe Por UC'!$C:$C,'Infos Clientes'!$B11,'Detalhe Por UC'!$R:$R,'Infos Clientes'!AU$2))
B12: 10/162736-3 | C12: =ROW(F12) -> 12 | D12: IGREJA DO EVANGELHO QUADRANGULAR | E12: 360 | F12: 62.955.505/1973-60 | G12: gelcimarsouza1220@gmail.com | H12: 10/162736-3 | I12: BT | J12: trifasico | K12: GIROSSOL II | M12: 0.25 | Q12: =IF(_xlfn.MINIFS('Detalhe Por UC'!R:R,'Detalhe Por UC'!C:C,B12,'Detalhe Por UC'!AD:AD,">"&0)=0,"",_xlfn.MINIFS('Detalhe Por UC'!R:R,'Detalhe Por UC'!C:C,B12,'Detalhe Por UC'!AD:AD,">"&0)) -> 45627 | R12: =IF(P12<>"ATIVO",0, IF(OR(Q12="",Q12=0,O12=0),O12, O12-ROUND((MAX('Detalhe Por UC'!R:R) -Q12)/(365/12),0))) -> 0 | T12: 185.66667 | U12: =IFERROR((SUMIFS(W12:CN12,$W$2:$CN$2,">"&$Q$1-365,$W$2:$CN$2,"<="&$Q$1)/COUNTIFS(W12:CN12,">="&0,$W$2:$CN$2,">"&$Q$1-365,$W$2:$CN$2,"<="&$Q$1)),"") -> 299.4 | W12: 166 | X12: 295 | Y12: 180 | Z12: 195 | AA12: 251 | AB12: 157 | AC12: 114 | AD12: 89 | AE12: 97 | AF12: 139 | AG12: 255 | AH12: 184 | AI12: 235 | AJ12: =IF(SUMIFS('Detalhe Por UC'!$AB:$AB,'Detalhe Por UC'!$C:$C,'Infos Clientes'!$B12,'Detalhe Por UC'!$R:$R,'Infos Clientes'!AJ$2)=0,"", SUMIFS('Detalhe Por UC'!$AB:$AB,'Detalhe Por UC'!$C:$C,'Infos Clientes'!$B12,'Detalhe Por UC'!$R:$R,'Infos Clientes'!AJ$2) +SUMIFS('Detalhe Por UC'!$AC:$AC,'Detalhe Por UC'!$C:$C,'Infos Clientes'!$B12,'Detalhe Por UC'!$R:$R,'Infos Clientes'!AJ$2)) -> 332 | AK12: =IF(SUMIFS('Detalhe Por UC'!$AB:$AB,'Detalhe Por UC'!$C:$C,'Infos Clientes'!$B12,'Detalhe Por UC'!$R:$R,'Infos Clientes'!AK$2)=0,"", SUMIFS('Detalhe Por UC'!$AB:$AB,'Detalhe Por UC'!$C:$C,'Infos Clientes'!$B12,'Detalhe Por UC'!$R:$R,'Infos Clientes'!AK$2) +SUMIFS('Detalhe Por UC'!$AC:$AC,'Detalhe Por UC'!$C:$C,'Infos Clientes'!$B12,'Detalhe Por UC'!$R:$R,'Infos Clientes'!AK$2)) -> 472 | AL12: =IF(SUMIFS('Detalhe Por UC'!$AB:$AB,'Detalhe Por UC'!$C:$C,'Infos Clientes'!$B12,'Detalhe Por UC'!$R:$R,'Infos Clientes'!AL$2)=0,"", SUMIFS('Detalhe Por UC'!$AB:$AB,'Detalhe Por UC'!$C:$C,'Infos Clientes'!$B12,'Detalhe Por UC'!$R:$R,'Infos Clientes'!AL$2) +SUMIFS('Detalhe Por UC'!$AC:$AC,'Detalhe Por UC'!$C:$C,'Infos Clientes'!$B12,'Detalhe Por UC'!$R:$R,'Infos Clientes'!AL$2)) -> 477 | AM12: =IF(SUMIFS('Detalhe Por UC'!$AB:$AB,'Detalhe Por UC'!$C:$C,'Infos Clientes'!$B12,'Detalhe Por UC'!$R:$R,'Infos Clientes'!AM$2)=0,"", SUMIFS('Detalhe Por UC'!$AB:$AB,'Detalhe Por UC'!$C:$C,'Infos Clientes'!$B12,'Detalhe Por UC'!$R:$R,'Infos Clientes'!AM$2) +SUMIFS('Detalhe Por UC'!$AC:$AC,'Detalhe Por UC'!$C:$C,'Infos Clientes'!$B12,'Detalhe Por UC'!$R:$R,'Infos Clientes'!AM$2)) -> 343 | AN12: =IF(SUMIFS('Detalhe Por UC'!$AB:$AB,'Detalhe Por UC'!$C:$C,'Infos Clientes'!$B12,'Detalhe Por UC'!$R:$R,'Infos Clientes'!AN$2)=0,"", SUMIFS('Detalhe Por UC'!$AB:$AB,'Detalhe Por UC'!$C:$C,'Infos Clientes'!$B12,'Detalhe Por UC'!$R:$R,'Infos Clientes'!AN$2) +SUMIFS('Detalhe Por UC'!$AC:$AC,'Detalhe Por UC'!$C:$C,'Infos Clientes'!$B12,'Detalhe Por UC'!$R:$R,'Infos Clientes'!AN$2)) -> 314 | AO12: =IF(SUMIFS('Detalhe Por UC'!$AB:$AB,'Detalhe Por UC'!$C:$C,'Infos Clientes'!$B12,'Detalhe Por UC'!$R:$R,'Infos Clientes'!AO$2)=0,"", SUMIFS('Detalhe Por UC'!$AB:$AB,'Detalhe Por UC'!$C:$C,'Infos Clientes'!$B12,'Detalhe Por UC'!$R:$R,'Infos Clientes'!AO$2) +SUMIFS('Detalhe Por UC'!$AC:$AC,'Detalhe Por UC'!$C:$C,'Infos Clientes'!$B12,'Detalhe Por UC'!$R:$R,'Infos Clientes'!AO$2)) -> 148 | AP12: =IF(SUMIFS('Detalhe Por UC'!$AB:$AB,'Detalhe Por UC'!$C:$C,'Infos Clientes'!$B12,'Detalhe Por UC'!$R:$R,'Infos Clientes'!AP$2)=0,"", SUMIFS('Detalhe Por UC'!$AB:$AB,'Detalhe Por UC'!$C:$C,'Infos Clientes'!$B12,'Detalhe Por UC'!$R:$R,'Infos Clientes'!AP$2) +SUMIFS('Detalhe Por UC'!$AC:$AC,'Detalhe Por UC'!$C:$C,'Infos Clientes'!$B12,'Detalhe Por UC'!$R:$R,'Infos Clientes'!AP$2)) | AQ12: =IF(SUMIFS('Detalhe Por UC'!$AB:$AB,'Detalhe Por UC'!$C:$C,'Infos Clientes'!$B12,'Detalhe Por UC'!$R:$R,'Infos Clientes'!AQ$2)=0,"", SUMIFS('Detalhe Por UC'!$AB:$AB,'Detalhe Por UC'!$C:$C,'Infos Clientes'!$B12,'Detalhe Por UC'!$R:$R,'Infos Clientes'!AQ$2) +SUMIFS('Detalhe Por UC'!$AC:$AC,'Detalhe Por UC'!$C:$C,'Infos Clientes'!$B12,'Detalhe Por UC'!$R:$R,'Infos Clientes'!AQ$2)) | ... AU12: =IF(SUMIFS('Detalhe Por UC'!$AB:$AB,'Detalhe Por UC'!$C:$C,'Infos Clientes'!$B12,'Detalhe Por UC'!$R:$R,'Infos Clientes'!AU$2)=0,"", SUMIFS('Detalhe Por UC'!$AB:$AB,'Detalhe Por UC'!$C:$C,'Infos Clientes'!$B12,'Detalhe Por UC'!$R:$R,'Infos Clientes'!AU$2) +SUMIFS('Detalhe Por UC'!$AC:$AC,'Detalhe Por UC'!$C:$C,'Infos Clientes'!$B12,'Detalhe Por UC'!$R:$R,'Infos Clientes'!AU$2))
B13: 10/1672452-8 | C13: =ROW(F13) -> 13 | D13: IGREJA DO EVANGELHO QUADRANGULAR | E13: 371 | F13: 62.955.505/0172-13 | G13: regiao371@gmail.com | H13: 10/1672452-8 | I13: BT | J13: trifasico | K13: GIROSSOL II | M13: 0.25 | Q13: =IF(_xlfn.MINIFS('Detalhe Por UC'!R:R,'Detalhe Por UC'!C:C,B13,'Detalhe Por UC'!AD:AD,">"&0)=0,"",_xlfn.MINIFS('Detalhe Por UC'!R:R,'Detalhe Por UC'!C:C,B13,'Detalhe Por UC'!AD:AD,">"&0)) -> 45627 | R13: =IF(P13<>"ATIVO",0, IF(OR(Q13="",Q13=0,O13=0),O13, O13-ROUND((MAX('Detalhe Por UC'!R:R) -Q13)/(365/12),0))) -> 0 | T13: 418.16667 | U13: =IFERROR((SUMIFS(W13:CN13,$W$2:$CN$2,">"&$Q$1-365,$W$2:$CN$2,"<="&$Q$1)/COUNTIFS(W13:CN13,">="&0,$W$2:$CN$2,">"&$Q$1-365,$W$2:$CN$2,"<="&$Q$1)),"") -> 379 | W13: 1396 | X13: 1383 | Y13: 864 | Z13: 558 | AA13: 592 | AB13: 554 | AC13: 290 | AD13: 251 | AE13: 291 | AF13: 263 | AG13: 358 | AH13: 301 | AI13: 377 | AJ13: =IF(SUMIFS('Detalhe Por UC'!$AB:$AB,'Detalhe Por UC'!$C:$C,'Infos Clientes'!$B13,'Detalhe Por UC'!$R:$R,'Infos Clientes'!AJ$2)=0,"", SUMIFS('Detalhe Por UC'!$AB:$AB,'Detalhe Por UC'!$C:$C,'Infos Clientes'!$B13,'Detalhe Por UC'!$R:$R,'Infos Clientes'!AJ$2) +SUMIFS('Detalhe Por UC'!$AC:$AC,'Detalhe Por UC'!$C:$C,'Infos Clientes'!$B13,'Detalhe Por UC'!$R:$R,'Infos Clientes'!AJ$2)) -> 319 | AK13: =IF(SUMIFS('Detalhe Por UC'!$AB:$AB,'Detalhe Por UC'!$C:$C,'Infos Clientes'!$B13,'Detalhe Por UC'!$R:$R,'Infos Clientes'!AK$2)=0,"", SUMIFS('Detalhe Por UC'!$AB:$AB,'Detalhe Por UC'!$C:$C,'Infos Clientes'!$B13,'Detalhe Por UC'!$R:$R,'Infos Clientes'!AK$2) +SUMIFS('Detalhe Por UC'!$AC:$AC,'Detalhe Por UC'!$C:$C,'Infos Clientes'!$B13,'Detalhe Por UC'!$R:$R,'Infos Clientes'!AK$2)) -> 564 | AL13: =IF(SUMIFS('Detalhe Por UC'!$AB:$AB,'Detalhe Por UC'!$C:$C,'Infos Clientes'!$B13,'Detalhe Por UC'!$R:$R,'Infos Clientes'!AL$2)=0,"", SUMIFS('Detalhe Por UC'!$AB:$AB,'Detalhe Por UC'!$C:$C,'Infos Clientes'!$B13,'Detalhe Por UC'!$R:$R,'Infos Clientes'!AL$2) +SUMIFS('Detalhe Por UC'!$AC:$AC,'Detalhe Por UC'!$C:$C,'Infos Clientes'!$B13,'Detalhe Por UC'!$R:$R,'Infos Clientes'!AL$2)) -> 476 | AM13: =IF(SUMIFS('Detalhe Por UC'!$AB:$AB,'Detalhe Por UC'!$C:$C,'Infos Clientes'!$B13,'Detalhe Por UC'!$R:$R,'Infos Clientes'!AM$2)=0,"", SUMIFS('Detalhe Por UC'!$AB:$AB,'Detalhe Por UC'!$C:$C,'Infos Clientes'!$B13,'Detalhe Por UC'!$R:$R,'Infos Clientes'!AM$2) +SUMIFS('Detalhe Por UC'!$AC:$AC,'Detalhe Por UC'!$C:$C,'Infos Clientes'!$B13,'Detalhe Por UC'!$R:$R,'Infos Clientes'!AM$2)) -> 523 | AN13: =IF(SUMIFS('Detalhe Por UC'!$AB:$AB,'Detalhe Por UC'!$C:$C,'Infos Clientes'!$B13,'Detalhe Por UC'!$R:$R,'Infos Clientes'!AN$2)=0,"", SUMIFS('Detalhe Por UC'!$AB:$AB,'Detalhe Por UC'!$C:$C,'Infos Clientes'!$B13,'Detalhe Por UC'!$R:$R,'Infos Clientes'!AN$2) +SUMIFS('Detalhe Por UC'!$AC:$AC,'Detalhe Por UC'!$C:$C,'Infos Clientes'!$B13,'Detalhe Por UC'!$R:$R,'Infos Clientes'!AN$2)) -> 456 | AO13: =IF(SUMIFS('Detalhe Por UC'!$AB:$AB,'Detalhe Por UC'!$C:$C,'Infos Clientes'!$B13,'Detalhe Por UC'!$R:$R,'Infos Clientes'!AO$2)=0,"", SUMIFS('Detalhe Por UC'!$AB:$AB,'Detalhe Por UC'!$C:$C,'Infos Clientes'!$B13,'Detalhe Por UC'!$R:$R,'Infos Clientes'!AO$2) +SUMIFS('Detalhe Por UC'!$AC:$AC,'Detalhe Por UC'!$C:$C,'Infos Clientes'!$B13,'Detalhe Por UC'!$R:$R,'Infos Clientes'!AO$2)) -> 283 | AP13: =IF(SUMIFS('Detalhe Por UC'!$AB:$AB,'Detalhe Por UC'!$C:$C,'Infos Clientes'!$B13,'Detalhe Por UC'!$R:$R,'Infos Clientes'!AP$2)=0,"", SUMIFS('Detalhe Por UC'!$AB:$AB,'Detalhe Por UC'!$C:$C,'Infos Clientes'!$B13,'Detalhe Por UC'!$R:$R,'Infos Clientes'!AP$2) +SUMIFS('Detalhe Por UC'!$AC:$AC,'Detalhe Por UC'!$C:$C,'Infos Clientes'!$B13,'Detalhe Por UC'!$R:$R,'Infos Clientes'!AP$2)) -> 164 | AQ13: =IF(SUMIFS('Detalhe Por UC'!$AB:$AB,'Detalhe Por UC'!$C:$C,'Infos Clientes'!$B13,'Detalhe Por UC'!$R:$R,'Infos Clientes'!AQ$2)=0,"", SUMIFS('Detalhe Por UC'!$AB:$AB,'Detalhe Por UC'!$C:$C,'Infos Clientes'!$B13,'Detalhe Por UC'!$R:$R,'Infos Clientes'!AQ$2) +SUMIFS('Detalhe Por UC'!$AC:$AC,'Detalhe Por UC'!$C:$C,'Infos Clientes'!$B13,'Detalhe Por UC'!$R:$R,'Infos Clientes'!AQ$2)) -> 197 | ... AU13: =IF(SUMIFS('Detalhe Por UC'!$AB:$AB,'Detalhe Por UC'!$C:$C,'Infos Clientes'!$B13,'Detalhe Por UC'!$R:$R,'Infos Clientes'!AU$2)=0,"", SUMIFS('Detalhe Por UC'!$AB:$AB,'Detalhe Por UC'!$C:$C,'Infos Clientes'!$B13,'Detalhe Por UC'!$R:$R,'Infos Clientes'!AU$2) +SUMIFS('Detalhe Por UC'!$AC:$AC,'Detalhe Por UC'!$C:$C,'Infos Clientes'!$B13,'Detalhe Por UC'!$R:$R,'Infos Clientes'!AU$2))
B14: 10/1695011-5 | C14: =ROW(F14) -> 14 | D14: IGREJA DO EVANGELHO QUADRANGULAR | E14: 306 | F14: 62.955.505/4612-10 | G14: prmarcelo.quadrangular@gmail.com | H14: 10/1695011-5 | I14: BT | J14: trifasico | K14: GIROSSOL II | M14: 0.25 | Q14: =IF(_xlfn.MINIFS('Detalhe Por UC'!R:R,'Detalhe Por UC'!C:C,B14,'Detalhe Por UC'!AD:AD,">"&0)=0,"",_xlfn.MINIFS('Detalhe Por UC'!R:R,'Detalhe Por UC'!C:C,B14,'Detalhe Por UC'!AD:AD,">"&0)) -> 45627 | R14: =IF(P14<>"ATIVO",0, IF(OR(Q14="",Q14=0,O14=0),O14, O14-ROUND((MAX('Detalhe Por UC'!R:R) -Q14)/(365/12),0))) -> 0 | T14: 511.41667 | U14: =IFERROR((SUMIFS(W14:CN14,$W$2:$CN$2,">"&$Q$1-365,$W$2:$CN$2,"<="&$Q$1)/COUNTIFS(W14:CN14,">="&0,$W$2:$CN$2,">"&$Q$1-365,$W$2:$CN$2,"<="&$Q$1)),"") -> 754.16667 | W14: 284 | X14: 290 | Y14: 169 | Z14: 340 | AA14: 274 | AB14: 260 | AC14: 283 | AD14: 441 | AE14: 428 | AF14: 565 | AG14: 866 | AH14: 786 | AI14: 892 | AJ14: =IF(SUMIFS('Detalhe Por UC'!$AB:$AB,'Detalhe Por UC'!$C:$C,'Infos Clientes'!$B14,'Detalhe Por UC'!$R:$R,'Infos Clientes'!AJ$2)=0,"", SUMIFS('Detalhe Por UC'!$AB:$AB,'Detalhe Por UC'!$C:$C,'Infos Clientes'!$B14,'Detalhe Por UC'!$R:$R,'Infos Clientes'!AJ$2) +SUMIFS('Detalhe Por UC'!$AC:$AC,'Detalhe Por UC'!$C:$C,'Infos Clientes'!$B14,'Detalhe Por UC'!$R:$R,'Infos Clientes'!AJ$2)) -> 833 | AK14: =IF(SUMIFS('Detalhe Por UC'!$AB:$AB,'Detalhe Por UC'!$C:$C,'Infos Clientes'!$B14,'Detalhe Por UC'!$R:$R,'Infos Clientes'!AK$2)=0,"", SUMIFS('Detalhe Por UC'!$AB:$AB,'Detalhe Por UC'!$C:$C,'Infos Clientes'!$B14,'Detalhe Por UC'!$R:$R,'Infos Clientes'!AK$2) +SUMIFS('Detalhe Por UC'!$AC:$AC,'Detalhe Por UC'!$C:$C,'Infos Clientes'!$B14,'Detalhe Por UC'!$R:$R,'Infos Clientes'!AK$2)) -> 930 | AL14: =IF(SUMIFS('Detalhe Por UC'!$AB:$AB,'Detalhe Por UC'!$C:$C,'Infos Clientes'!$B14,'Detalhe Por UC'!$R:$R,'Infos Clientes'!AL$2)=0,"", SUMIFS('Detalhe Por UC'!$AB:$AB,'Detalhe Por UC'!$C:$C,'Infos Clientes'!$B14,'Detalhe Por UC'!$R:$R,'Infos Clientes'!AL$2) +SUMIFS('Detalhe Por UC'!$AC:$AC,'Detalhe Por UC'!$C:$C,'Infos Clientes'!$B14,'Detalhe Por UC'!$R:$R,'Infos Clientes'!AL$2)) -> 873 | AM14: =IF(SUMIFS('Detalhe Por UC'!$AB:$AB,'Detalhe Por UC'!$C:$C,'Infos Clientes'!$B14,'Detalhe Por UC'!$R:$R,'Infos Clientes'!AM$2)=0,"", SUMIFS('Detalhe Por UC'!$AB:$AB,'Detalhe Por UC'!$C:$C,'Infos Clientes'!$B14,'Detalhe Por UC'!$R:$R,'Infos Clientes'!AM$2) +SUMIFS('Detalhe Por UC'!$AC:$AC,'Detalhe Por UC'!$C:$C,'Infos Clientes'!$B14,'Detalhe Por UC'!$R:$R,'Infos Clientes'!AM$2)) -> 885 | AN14: =IF(SUMIFS('Detalhe Por UC'!$AB:$AB,'Detalhe Por UC'!$C:$C,'Infos Clientes'!$B14,'Detalhe Por UC'!$R:$R,'Infos Clientes'!AN$2)=0,"", SUMIFS('Detalhe Por UC'!$AB:$AB,'Detalhe Por UC'!$C:$C,'Infos Clientes'!$B14,'Detalhe Por UC'!$R:$R,'Infos Clientes'!AN$2) +SUMIFS('Detalhe Por UC'!$AC:$AC,'Detalhe Por UC'!$C:$C,'Infos Clientes'!$B14,'Detalhe Por UC'!$R:$R,'Infos Clientes'!AN$2)) -> 758 | AO14: =IF(SUMIFS('Detalhe Por UC'!$AB:$AB,'Detalhe Por UC'!$C:$C,'Infos Clientes'!$B14,'Detalhe Por UC'!$R:$R,'Infos Clientes'!AO$2)=0,"", SUMIFS('Detalhe Por UC'!$AB:$AB,'Detalhe Por UC'!$C:$C,'Infos Clientes'!$B14,'Detalhe Por UC'!$R:$R,'Infos Clientes'!AO$2) +SUMIFS('Detalhe Por UC'!$AC:$AC,'Detalhe Por UC'!$C:$C,'Infos Clientes'!$B14,'Detalhe Por UC'!$R:$R,'Infos Clientes'!AO$2)) -> 599 | AP14: =IF(SUMIFS('Detalhe Por UC'!$AB:$AB,'Detalhe Por UC'!$C:$C,'Infos Clientes'!$B14,'Detalhe Por UC'!$R:$R,'Infos Clientes'!AP$2)=0,"", SUMIFS('Detalhe Por UC'!$AB:$AB,'Detalhe Por UC'!$C:$C,'Infos Clientes'!$B14,'Detalhe Por UC'!$R:$R,'Infos Clientes'!AP$2) +SUMIFS('Detalhe Por UC'!$AC:$AC,'Detalhe Por UC'!$C:$C,'Infos Clientes'!$B14,'Detalhe Por UC'!$R:$R,'Infos Clientes'!AP$2)) -> 548 | AQ14: =IF(SUMIFS('Detalhe Por UC'!$AB:$AB,'Detalhe Por UC'!$C:$C,'Infos Clientes'!$B14,'Detalhe Por UC'!$R:$R,'Infos Clientes'!AQ$2)=0,"", SUMIFS('Detalhe Por UC'!$AB:$AB,'Detalhe Por UC'!$C:$C,'Infos Clientes'!$B14,'Detalhe Por UC'!$R:$R,'Infos Clientes'!AQ$2) +SUMIFS('Detalhe Por UC'!$AC:$AC,'Detalhe Por UC'!$C:$C,'Infos Clientes'!$B14,'Detalhe Por UC'!$R:$R,'Infos Clientes'!AQ$2)) -> 538 | ... AU14: =IF(SUMIFS('Detalhe Por UC'!$AB:$AB,'Detalhe Por UC'!$C:$C,'Infos Clientes'!$B14,'Detalhe Por UC'!$R:$R,'Infos Clientes'!AU$2)=0,"", SUMIFS('Detalhe Por UC'!$AB:$AB,'Detalhe Por UC'!$C:$C,'Infos Clientes'!$B14,'Detalhe Por UC'!$R:$R,'Infos Clientes'!AU$2) +SUMIFS('Detalhe Por UC'!$AC:$AC,'Detalhe Por UC'!$C:$C,'Infos Clientes'!$B14,'Detalhe Por UC'!$R:$R,'Infos Clientes'!AU$2))
... B43: 10/987178-1 | C43: =ROW(F43) -> 43 | D43: IGREJA DO EVANGELHO QUADRANGULAR | E43: 358 | F43: 62.955.505/0155-12 | G43: lucianop.duarte@outlook.com | H43: 10/987178-1 | I43: BT | J43: trifasico | K43: GIROSSOL II | M43: 0.25 | Q43: =IF(_xlfn.MINIFS('Detalhe Por UC'!R:R,'Detalhe Por UC'!C:C,B43,'Detalhe Por UC'!AD:AD,">"&0)=0,"",_xlfn.MINIFS('Detalhe Por UC'!R:R,'Detalhe Por UC'!C:C,B43,'Detalhe Por UC'!AD:AD,">"&0)) -> 45627 | R43: =IF(P43<>"ATIVO",0, IF(OR(Q43="",Q43=0,O43=0),O43, O43-ROUND((MAX('Detalhe Por UC'!R:R) -Q43)/(365/12),0))) -> 0 | T43: 123.5 | U43: =IFERROR((SUMIFS(W43:CN43,$W$2:$CN$2,">"&$Q$1-365,$W$2:$CN$2,"<="&$Q$1)/COUNTIFS(W43:CN43,">="&0,$W$2:$CN$2,">"&$Q$1-365,$W$2:$CN$2,"<="&$Q$1)),"") -> 147.09091 | W43: 148 | X43: 145 | Y43: 151 | Z43: 176 | AA43: 185 | AB43: 144 | AC43: 88 | AD43: 83 | AE43: 116 | AF43: 75 | AG43: 97 | AH43: 120 | AI43: 135 | AJ43: =IF(SUMIFS('Detalhe Por UC'!$AB:$AB,'Detalhe Por UC'!$C:$C,'Infos Clientes'!$B43,'Detalhe Por UC'!$R:$R,'Infos Clientes'!AJ$2)=0,"", SUMIFS('Detalhe Por UC'!$AB:$AB,'Detalhe Por UC'!$C:$C,'Infos Clientes'!$B43,'Detalhe Por UC'!$R:$R,'Infos Clientes'!AJ$2) +SUMIFS('Detalhe Por UC'!$AC:$AC,'Detalhe Por UC'!$C:$C,'Infos Clientes'!$B43,'Detalhe Por UC'!$R:$R,'Infos Clientes'!AJ$2)) -> 112 | AK43: =IF(SUMIFS('Detalhe Por UC'!$AB:$AB,'Detalhe Por UC'!$C:$C,'Infos Clientes'!$B43,'Detalhe Por UC'!$R:$R,'Infos Clientes'!AK$2)=0,"", SUMIFS('Detalhe Por UC'!$AB:$AB,'Detalhe Por UC'!$C:$C,'Infos Clientes'!$B43,'Detalhe Por UC'!$R:$R,'Infos Clientes'!AK$2) +SUMIFS('Detalhe Por UC'!$AC:$AC,'Detalhe Por UC'!$C:$C,'Infos Clientes'!$B43,'Detalhe Por UC'!$R:$R,'Infos Clientes'!AK$2)) -> 110 | AL43: =IF(SUMIFS('Detalhe Por UC'!$AB:$AB,'Detalhe Por UC'!$C:$C,'Infos Clientes'!$B43,'Detalhe Por UC'!$R:$R,'Infos Clientes'!AL$2)=0,"", SUMIFS('Detalhe Por UC'!$AB:$AB,'Detalhe Por UC'!$C:$C,'Infos Clientes'!$B43,'Detalhe Por UC'!$R:$R,'Infos Clientes'!AL$2) +SUMIFS('Detalhe Por UC'!$AC:$AC,'Detalhe Por UC'!$C:$C,'Infos Clientes'!$B43,'Detalhe Por UC'!$R:$R,'Infos Clientes'!AL$2)) -> 137 | AM43: =IF(SUMIFS('Detalhe Por UC'!$AB:$AB,'Detalhe Por UC'!$C:$C,'Infos Clientes'!$B43,'Detalhe Por UC'!$R:$R,'Infos Clientes'!AM$2)=0,"", SUMIFS('Detalhe Por UC'!$AB:$AB,'Detalhe Por UC'!$C:$C,'Infos Clientes'!$B43,'Detalhe Por UC'!$R:$R,'Infos Clientes'!AM$2) +SUMIFS('Detalhe Por UC'!$AC:$AC,'Detalhe Por UC'!$C:$C,'Infos Clientes'!$B43,'Detalhe Por UC'!$R:$R,'Infos Clientes'!AM$2)) -> 113 | AN43: =IF(SUMIFS('Detalhe Por UC'!$AB:$AB,'Detalhe Por UC'!$C:$C,'Infos Clientes'!$B43,'Detalhe Por UC'!$R:$R,'Infos Clientes'!AN$2)=0,"", SUMIFS('Detalhe Por UC'!$AB:$AB,'Detalhe Por UC'!$C:$C,'Infos Clientes'!$B43,'Detalhe Por UC'!$R:$R,'Infos Clientes'!AN$2) +SUMIFS('Detalhe Por UC'!$AC:$AC,'Detalhe Por UC'!$C:$C,'Infos Clientes'!$B43,'Detalhe Por UC'!$R:$R,'Infos Clientes'!AN$2)) -> 121 | AO43: =IF(SUMIFS('Detalhe Por UC'!$AB:$AB,'Detalhe Por UC'!$C:$C,'Infos Clientes'!$B43,'Detalhe Por UC'!$R:$R,'Infos Clientes'!AO$2)=0,"", SUMIFS('Detalhe Por UC'!$AB:$AB,'Detalhe Por UC'!$C:$C,'Infos Clientes'!$B43,'Detalhe Por UC'!$R:$R,'Infos Clientes'!AO$2) +SUMIFS('Detalhe Por UC'!$AC:$AC,'Detalhe Por UC'!$C:$C,'Infos Clientes'!$B43,'Detalhe Por UC'!$R:$R,'Infos Clientes'!AO$2)) | AP43: =IF(SUMIFS('Detalhe Por UC'!$AB:$AB,'Detalhe Por UC'!$C:$C,'Infos Clientes'!$B43,'Detalhe Por UC'!$R:$R,'Infos Clientes'!AP$2)=0,"", SUMIFS('Detalhe Por UC'!$AB:$AB,'Detalhe Por UC'!$C:$C,'Infos Clientes'!$B43,'Detalhe Por UC'!$R:$R,'Infos Clientes'!AP$2) +SUMIFS('Detalhe Por UC'!$AC:$AC,'Detalhe Por UC'!$C:$C,'Infos Clientes'!$B43,'Detalhe Por UC'!$R:$R,'Infos Clientes'!AP$2)) -> 181 | AQ43: =IF(SUMIFS('Detalhe Por UC'!$AB:$AB,'Detalhe Por UC'!$C:$C,'Infos Clientes'!$B43,'Detalhe Por UC'!$R:$R,'Infos Clientes'!AQ$2)=0,"", SUMIFS('Detalhe Por UC'!$AB:$AB,'Detalhe Por UC'!$C:$C,'Infos Clientes'!$B43,'Detalhe Por UC'!$R:$R,'Infos Clientes'!AQ$2) +SUMIFS('Detalhe Por UC'!$AC:$AC,'Detalhe Por UC'!$C:$C,'Infos Clientes'!$B43,'Detalhe Por UC'!$R:$R,'Infos Clientes'!AQ$2)) -> 212 | ... AU43: =IF(SUMIFS('Detalhe Por UC'!$AB:$AB,'Detalhe Por UC'!$C:$C,'Infos Clientes'!$B43,'Detalhe Por UC'!$R:$R,'Infos Clientes'!AU$2)=0,"", SUMIFS('Detalhe Por UC'!$AB:$AB,'Detalhe Por UC'!$C:$C,'Infos Clientes'!$B43,'Detalhe Por UC'!$R:$R,'Infos Clientes'!AU$2) +SUMIFS('Detalhe Por UC'!$AC:$AC,'Detalhe Por UC'!$C:$C,'Infos Clientes'!$B43,'Detalhe Por UC'!$R:$R,'Infos Clientes'!AU$2))
